<mujoco model="elf2_dof25">
  <compiler angle="radian" autolimits="true" meshdir="assets"/>
	
  <default>
	<light castshadow="false" />
	<geom  condim='4' solref='0.001 5' friction='0.5 0.5 0.5' contype='0' conaffinity='0'/>
	<default class="visual">
		<geom contype="0" conaffinity="0" type="mesh" density="0" />
	</default>
	<default class="collision">
		<geom contype="1" conaffinity="1"/>
	</default>
	<default class='obstacle'>
		<geom material='obstacle' condim='3' contype='1' conaffinity='15'/>
	</default>
	<joint limited='true' damping="0.1" armature="0.01" frictionloss="0.01" />
	<motor ctrllimited='true'/>
  </default>

  <visual>
    <rgba com="0.502 1.0 0 1.0" fog="0 0 0 1" contactpoint="0.4 0.4 0.4 0.8"  contactforce="0.0 0.9 0.9 0.5" />
    <scale com="0.05" forcewidth="0.04" contactwidth="0.10" contactheight="0.005" selectpoint="0.01" />
    <map force="0.005" />
  </visual>

  <option timestep="0.001" />

  <asset>
    <material name="black" rgba="0.2 0.2 0.2 1"/>
    <material name="metal" rgba="0.2 0.2 0.2 1"/>
	<material name="plastic" rgba="0.3 0.4 0.4 1"/>
	
    <mesh name="base_link" file="base_link.STL"/>
    <mesh name="l_hip_z_link" file="l_hip_z_link.STL"/>
    <mesh name="l_hip_x_link" file="l_hip_x_link.STL"/>
    <mesh name="l_hip_y_link" file="l_hip_y_link.STL"/>
    <mesh name="l_knee_y_link" file="l_knee_y_link.STL"/>
    <mesh name="l_ankle_y_link" file="l_ankle_y_link.STL"/>
    <mesh name="l_ankle_x_link" file="l_ankle_x_link.STL"/>
    <mesh name="r_hip_z_link" file="r_hip_z_link.STL"/>
    <mesh name="r_hip_x_link" file="r_hip_x_link.STL"/>
    <mesh name="r_hip_y_link" file="r_hip_y_link.STL"/>
    <mesh name="r_knee_y_link" file="r_knee_y_link.STL"/>
    <mesh name="r_ankle_y_link" file="r_ankle_y_link.STL"/>
    <mesh name="r_ankle_x_link" file="r_ankle_x_link.STL"/>
    <mesh name="waist_z_link" file="waist_z_link.STL"/>
    <mesh name="waist_x_link" file="waist_x_link.STL"/>
    <mesh name="waist_y_link" file="waist_y_link.STL"/>
    <mesh name="l_shld_y_link" file="l_shld_y_link.STL"/>
    <mesh name="l_shld_x_link" file="l_shld_x_link.STL"/>
    <mesh name="l_shld_z_link" file="l_shld_z_link.STL"/>
    <mesh name="l_elb_y_link" file="l_elb_y_link.STL"/>
    <mesh name="l_elb_z_link" file="l_elb_z_link.STL"/>
    <mesh name="r_shld_y_link" file="r_shld_y_link.STL"/>
    <mesh name="r_shld_x_link" file="r_shld_x_link.STL"/>
    <mesh name="r_shld_z_link" file="r_shld_z_link.STL"/>
    <mesh name="r_elb_y_link" file="r_elb_y_link.STL"/>
    <mesh name="r_elb_z_link" file="r_elb_z_link.STL"/>

    <texture type="skybox" builtin="gradient" width="512" height="512" rgb1=".4 .6 .8"   rgb2="0 0 0" />
    <texture name="texgeom" type="cube" builtin="flat" mark="cross" width="128"  height="128"  rgb1="0.6 0.6 0.6" rgb2="0.6 0.6 0.6" markrgb="1 1 1" />
    <texture name="texplane" type="2d" builtin="checker" rgb1=".4 .4 .4" rgb2=".6 .6 .6"  width="512" height="512" />
    <material name='MatPlane' reflectance='0.3' texture="texplane" texrepeat="1 1"  texuniform="true" rgba=".7 .7 .7 1" />

  </asset>
  <worldbody>

    <light directional="true" diffuse=".8 .8 .8" pos="0 0 10" dir="0 0 -10" />
    <geom class="collision" name="floor" pos="0 0 0" type="plane" size="0 0 1" material="MatPlane" />
    <camera name="track" mode="targetbody" target="base_link" pos="0 -1.3 1.6" xyaxes="1 0 0 0 0.707 0.707" />

    <body name="base_link" pos="0 0 0.75" gravcomp="0">
      <inertial pos="0.00030047 8.28e-06 0.0354679" quat="0.497932 0.4979 -0.502049 0.502101" mass="3.24039" diaginertia="0.0241062 0.0228041 0.00335281"/>
      <joint name="world_joint" type="free"/>
      <geom class="collision" type="mesh" material="black" mesh="base_link"/>
      <site name="imu" pos="0 0 0" />
      <body name="l_hip_z_link" pos="0 0.1 -0.1008" gravcomp="0">
        <inertial pos="-0.0951743 -0.00029544 0.011577" quat="0.950348 -0.0165245 0.307379 -0.0456384" mass="1.26003" diaginertia="0.00318767 0.00299323 0.00121169"/>
        <joint name="l_hip_z_joint" pos="0 0 0" axis="0 0 1" range="-0.785 0.785"/>
        <geom type="mesh" material="metal" mesh="l_hip_z_link"/>
        <body name="l_hip_x_link" pos="0 0 0" gravcomp="0">
          <inertial pos="-0.00349545 -0.0501608 0.00015601" quat="0.578435 0.631575 0.35193 0.377717" mass="1.75826" diaginertia="0.00198223 0.00181137 0.00131094"/>
          <joint name="l_hip_x_joint" pos="0 0 0" axis="1 0 0" range="-0.523 0.785"/>
          <geom type="mesh" material="metal"  mesh="l_hip_x_link"/>
          <body name="l_hip_y_link" pos="0 0 0" gravcomp="0">
            <inertial pos="0.00237237 0.0240808 -0.0487449" quat="0.915126 -0.0824256 0.0170128 0.394286" mass="2.66296" diaginertia="0.0268551 0.0267772 0.00387364"/>
            <joint name="l_hip_y_joint" pos="0 0 0" axis="0 1 0" range="-2 1"/>
            <geom type="mesh" material="metal" mesh="l_hip_y_link"/>
            <body name="l_knee_y_link" pos="0 0 -0.3" gravcomp="0">
              <inertial pos="0.00711393 -0.00031499 -0.109778" quat="0.999281 -0.00839565 0.0304989 0.0209001" mass="1.63072" diaginertia="0.0104617 0.0101879 0.00137116"/>
              <joint name="l_knee_y_joint" pos="0 0 0" axis="0 1 0" range="0 2.355"/>
              <geom type="mesh" material="metal" mesh="l_knee_y_link"/>
              <body name="l_ankle_y_link" pos="0 0 -0.3" gravcomp="0">
                <inertial pos="0 0 -0.00046563" quat="0.5 0.5 -0.5 0.5" mass="0.0120696" diaginertia="3.01e-06 2.89e-06 3.4e-07"/>
                <joint name="l_ankle_y_joint" pos="0 0 0" axis="0 1 0" range="-1.134 0.872"/>
                <geom type="mesh" material="metal" mesh="l_ankle_y_link"/>
                <body name="l_ankle_x_link" pos="0 0 0" gravcomp="0">
                  <inertial pos="-0.00088171 0 -0.0224519" quat="0 0.710014 0 0.704188" mass="0.270642" diaginertia="0.000816706 0.00071745 0.000145444"/>
                  <joint name="l_ankle_x_joint" pos="0 0 0" axis="1 0 0" range="-0.349 0.349"/>
                  <geom class="collision" type="mesh" material="metal" mesh="l_ankle_x_link"/>
                  <site name="lf_tc" type="box" class="collision" size="0.1 0.042 0.005" pos="0.0 0 -0.035" rgba="0 0 0 0"/>
                </body>
              </body>
            </body>
          </body>
        </body>
      </body>
      <body name="r_hip_z_link" pos="0 -0.1 -0.1008" gravcomp="0">
        <inertial pos="-0.0951743 0.00029543 0.011577" quat="0.950348 0.0165245 0.307379 0.0456384" mass="1.26003" diaginertia="0.00318767 0.00299323 0.00121169"/>
        <joint name="r_hip_z_joint" pos="0 0 0" axis="0 0 1" range="-0.785 0.785"/>
        <geom type="mesh" material="black" mesh="r_hip_z_link"/>
        <body name="r_hip_x_link" pos="0 0 0" gravcomp="0">
          <inertial pos="-0.00349545 0.0501608 0.000156" quat="0.377717 0.35193 0.631575 0.578435" mass="1.75826" diaginertia="0.00198223 0.00181137 0.00131094"/>
          <joint name="r_hip_x_joint" pos="0 0 0" axis="1 0 0" range="-0.785 0.523"/>
          <geom type="mesh" material="metal" mesh="r_hip_x_link"/>
          <body name="r_hip_y_link" pos="0 0 0" gravcomp="0">
            <inertial pos="0.00237237 -0.0240808 -0.0487449" quat="0.394265 0.0170111 -0.0824261 0.915135" mass="2.66296" diaginertia="0.0268551 0.0267772 0.00387363"/>
            <joint name="r_hip_y_joint" pos="0 0 0" axis="0 1 0" range="-2 1"/>
            <geom type="mesh" material="metal" mesh="r_hip_y_link"/>
            <body name="r_knee_y_link" pos="0 0 -0.3" gravcomp="0">
              <inertial pos="0.00711396 0.00031502 -0.109778" quat="0.999281 0.00839515 0.0304983 -0.0208987" mass="1.63072" diaginertia="0.0104617 0.0101878 0.00137116"/>
              <joint name="r_knee_y_joint" pos="0 0 0" axis="0 1 0" range="0 2.355"/>
              <geom type="mesh" material="metal" mesh="r_knee_y_link"/>
              <body name="r_ankle_y_link" pos="0 0 -0.3" gravcomp="0">
                <inertial pos="0 0 -0.00046563" quat="0.5 0.5 -0.5 0.5" mass="0.0120696" diaginertia="3.01e-06 2.89e-06 3.4e-07"/>
                <joint name="r_ankle_y_joint" pos="0 0 0" axis="0 1 0" range="-1.134 0.872"/>
                <geom type="mesh" material="metal" mesh="r_ankle_y_link"/>
                <body name="r_ankle_x_link" pos="0 0 0" gravcomp="0">
                  <inertial pos="-0.00088171 0 -0.0224519" quat="0 0.710014 0 0.704188" mass="0.270642" diaginertia="0.000816706 0.00071745 0.000145444"/>
                  <joint name="r_ankle_x_joint" pos="0 0 0" axis="1 0 0" range="-0.349 0.349"/>
                  <geom class="collision" type="mesh" material="metal" mesh="r_ankle_x_link"/>
                  <site name="rf_tc" type="box" class="collision" size="0.1 0.042 0.005" pos="0.0 0 -0.035" rgba="0 0 0 0"/>
                </body>
              </body>
            </body>
          </body>
        </body>
      </body>
      <body name="waist_z_link" pos="0 0 0.1167" gravcomp="0">
        <inertial pos="-0.00448944 0 -0.0238919" quat="0 0.867095 0 0.498142" mass="0.21792" diaginertia="0.000150161 0.0001491 7.07387e-05"/>
        <joint name="waist_z_joint" pos="0 0 0" axis="0 0 1" range="-1.57 1.57"/>
        <geom type="mesh" material="black" mesh="waist_z_link"/>
        <body name="waist_x_link" pos="0 0 0" gravcomp="0">
          <inertial pos="0 0 0" quat="0.5 0.5 -0.5 0.5" mass="0.0531674" diaginertia="1.819e-05 9.7e-06 9.7e-06"/>
          <joint name="waist_x_joint" pos="0 0 0" axis="1 0 0" range="-0.262 0.262" damping="1.0"/>
          <geom type="mesh" material="black" mesh="waist_x_link"/>
          <body name="waist_y_link" pos="0 0 0" gravcomp="0">
            <inertial pos="-0.00308477 0.00223688 0.187396" quat="0.999724 -0.0229904 0.00436057 -0.00194245" mass="8.16458" diaginertia="0.126377 0.081479 0.0683309"/>
            <joint name="waist_y_joint" pos="0 0 0" axis="0 1 0" range="-0.523 0.523" damping="1.0"/>
            <geom class="collision" type="mesh" material="plastic" mesh="waist_y_link"/>
            <body name="l_shld_y_link" pos="0 0.21705 0.30075" gravcomp="0">
              <inertial pos="0.00068297 -0.00449372 2.22e-06" quat="0.435933 0.557654 -0.43314 0.558009" mass="0.53805" diaginertia="0.00032312 0.000307497 0.000290513"/>
              <joint name="l_shld_y_joint" pos="0 0 0" axis="0 1 0" range="-3.14 1.57"/>
              <geom type="mesh" material="metal" mesh="l_shld_y_link"/>
              <body name="l_shld_x_link" pos="0 0 0" gravcomp="0">
                <inertial pos="-2.047e-05 5.316e-05 -0.0616265" quat="0.511019 0.489093 0.494385 0.505204" mass="0.488475" diaginertia="0.000337096 0.000288412 0.000271922"/>
                <joint name="l_shld_x_joint" pos="0 0 0" axis="1 0 0" range="-0.5 1.57"/>
                <geom type="mesh" material="metal" mesh="l_shld_x_link"/>
                <body name="l_shld_z_link" pos="0 0 0" gravcomp="0">
                  <inertial pos="4.164e-05 0.00022669 -0.221278" quat="0.999947 0.000588453 -1.03341e-06 0.0102498" mass="0.593095" diaginertia="0.00136574 0.00133988 0.000303419"/>
                  <joint name="l_shld_z_joint" pos="0 0 0" axis="0 0 1" range="-0.785 0.785"/>
                  <geom type="mesh" material="metal" mesh="l_shld_z_link"/>
                  <body name="l_elb_y_link" pos="0 0 -0.24" gravcomp="0">
                    <inertial pos="5.192e-05 1.999e-05 -0.0856119" quat="0.999983 0.00544979 0.0018217 -0.000285656" mass="0.500057" diaginertia="0.000437132 0.000360437 0.000302651"/>
                    <joint name="l_elb_y_joint" pos="0 0 0" axis="0 1 0" range="-2.355 0.5"/>
                    <geom type="mesh" material="metal" mesh="l_elb_y_link"/>
                    <body name="l_elb_z_link" pos="0 0 0" gravcomp="0">
                      <inertial pos="1.97e-06 -1.756e-05 -0.182825" quat="1 0.00021844 2.91405e-05 -8.74832e-05" mass="0.134574" diaginertia="0.00040001 0.00039996 5.66199e-05"/>
                      <joint name="l_elb_z_joint" pos="0 0 0" axis="0 0 1" range="-0.785 0.785"/>
                      <geom type="mesh" material="metal" mesh="l_elb_z_link"/>
                    </body>
                  </body>
                </body>
              </body>
            </body>
            <body name="r_shld_y_link" pos="0 -0.21705 0.30075" gravcomp="0">
              <inertial pos="0.00068297 0.00449372 -2.22e-06" quat="0.558009 0.43314 -0.557654 0.435933" mass="0.53805" diaginertia="0.00032312 0.000307497 0.000290513"/>
              <joint name="r_shld_y_joint" pos="0 0 0" axis="0 1 0" range="-3.14 1.57"/>
              <geom type="mesh" material="metal" mesh="r_shld_y_link"/>
              <body name="r_shld_x_link" pos="0 0 0" gravcomp="0">
                <inertial pos="2.047e-05 -5.316e-05 -0.0616265" quat="0.489093 0.511019 0.505204 0.494385" mass="0.488475" diaginertia="0.000337096 0.000288412 0.000271922"/>
                <joint name="r_shld_x_joint" pos="0 0 0" axis="1 0 0" range="-1.57 0.5"/>
                <geom type="mesh" material="metal" mesh="r_shld_x_link"/>
                <body name="r_shld_z_link" pos="0 0 0" gravcomp="0">
                  <inertial pos="-4.164e-05 -0.00022669 -0.221278" quat="0.999947 -0.000588453 1.03341e-06 0.0102498" mass="0.593095" diaginertia="0.00136574 0.00133988 0.000303419"/>
                  <joint name="r_shld_z_joint" pos="0 0 0" axis="0 0 1" range="-0.785 0.785"/>
                  <geom type="mesh" material="metal" mesh="r_shld_z_link"/>
                  <body name="r_elb_y_link" pos="0 0 -0.24" gravcomp="0">
                    <inertial pos="-5.192e-05 -1.999e-05 -0.0856119" quat="0.999983 -0.00544979 -0.0018217 -0.000285656" mass="0.500057" diaginertia="0.000437132 0.000360437 0.000302651"/>
                    <joint name="r_elb_y_joint" pos="0 0 0" axis="0 1 0" range="-2.355 0.5"/>
                    <geom type="mesh" material="metal" mesh="r_elb_y_link"/>
                    <body name="r_elb_z_link" pos="0 0 0" gravcomp="0">
                      <inertial pos="-1.97e-06 1.756e-05 -0.182825" quat="1 -0.00021844 -2.91405e-05 -8.74832e-05" mass="0.134574" diaginertia="0.00040001 0.00039996 5.66199e-05"/>
                      <joint name="r_elb_z_joint" pos="0 0 0" axis="0 0 1" range="-0.785 0.785"/>
                      <geom type="mesh" material="metal" mesh="r_elb_z_link"/>
                    </body>
                  </body>
                </body>
              </body>
            </body>
          </body>
        </body>
      </body>
    </body>
  </worldbody>

  <actuator>
	<!-- left leg -->
    <motor name="l_hip_z_joint" joint="l_hip_z_joint" gear="1" ctrllimited='true' ctrlrange='-20 20' />
    <motor name="l_hip_x_joint" joint="l_hip_x_joint" gear="1" ctrllimited='true' ctrlrange='-40 40' />
    <motor name="l_hip_y_joint" joint="l_hip_y_joint" gear="1" ctrllimited='true' ctrlrange='-100 100' />
    <motor name="l_knee_y_joint" joint="l_knee_y_joint" gear="1" ctrllimited='true' ctrlrange='-120 120' />
    <motor name="l_ankle_y_joint" joint="l_ankle_y_joint" gear="1" ctrllimited='true' ctrlrange='-14 14' />
    <motor name="l_ankle_x_joint" joint="l_ankle_x_joint" gear="1" ctrllimited='true' ctrlrange='-7 7' />
	
	<!-- right leg -->
    <motor name="r_hip_z_joint" joint="r_hip_z_joint" gear="1" ctrllimited='true' ctrlrange='-20 20' />
    <motor name="r_hip_x_joint" joint="r_hip_x_joint" gear="1" ctrllimited='true' ctrlrange='-40 40' />
    <motor name="r_hip_y_joint" joint="r_hip_y_joint" gear="1" ctrllimited='true' ctrlrange='-100 100' />
    <motor name="r_knee_y_joint" joint="r_knee_y_joint" gear="1" ctrllimited='true' ctrlrange='-120 120' />
    <motor name="r_ankle_y_joint" joint="r_ankle_y_joint" gear="1" ctrllimited='true' ctrlrange='-14 14' />
    <motor name="r_ankle_x_joint" joint="r_ankle_x_joint" gear="1" ctrllimited='true' ctrlrange='-7 7' />
	
	<!-- waist -->
    <motor name="waist_z_joint" joint="waist_z_joint" gear="1" ctrllimited='true' ctrlrange='-50 50' />
    <motor name="waist_x_joint" joint="waist_x_joint" gear="1" ctrllimited='true' ctrlrange='-50 50' />
    <motor name="waist_y_joint" joint="waist_y_joint" gear="1" ctrllimited='true' ctrlrange='-50 50' />
	
	<!-- legt arm -->
    <motor name="l_shld_y_joint" joint="l_shld_y_joint" gear="1" ctrllimited='true' ctrlrange='-27 27' />
    <motor name="l_shld_x_joint" joint="l_shld_x_joint" gear="1" ctrllimited='true' ctrlrange='-27 27' />
    <motor name="l_shld_z_joint" joint="l_shld_z_joint" gear="1" ctrllimited='true' ctrlrange='-7 7' />
    <motor name="l_elb_y_joint" joint="l_elb_y_joint" gear="1" ctrllimited='true' ctrlrange='-27 27' />
    <motor name="l_elb_z_joint" joint="l_elb_z_joint" gear="1" ctrllimited='true' ctrlrange='-7 7' />
	
	<!-- right arm -->
    <motor name="r_shld_y_joint" joint="r_shld_y_joint" gear="1" ctrllimited='true' ctrlrange='-27 27' />
    <motor name="r_shld_x_joint" joint="r_shld_x_joint" gear="1" ctrllimited='true' ctrlrange='-27 27' />
    <motor name="r_shld_z_joint" joint="r_shld_z_joint" gear="1" ctrllimited='true' ctrlrange='-7 7' />
    <motor name="r_elb_y_joint" joint="r_elb_y_joint" gear="1" ctrllimited='true' ctrlrange='-27 27' />
    <motor name="r_elb_z_joint" joint="r_elb_z_joint" gear="1" ctrllimited='true' ctrlrange='-7 7' />

  </actuator>

  <sensor>
    <framequat name="Body_Quat" objtype="site" objname="imu" />
    <gyro name="Body_Gyro" site="imu" />
    <accelerometer name="Body_Acc" site="imu" />

    <!-- joint pos sensor-->
    <jointpos name="l_hip_z_joint_pos" joint="l_hip_z_joint" />
    <jointpos name="l_hip_x_joint_pos" joint="l_hip_x_joint" />
    <jointpos name="l_hip_y_joint_pos" joint="l_hip_y_joint" />
    <jointpos name="l_knee_y_joint_pos" joint="l_knee_y_joint" />
    <jointpos name="l_ankle_y_joint_pos" joint="l_ankle_y_joint" />
    <jointpos name="l_ankle_x_joint_pos" joint="l_ankle_x_joint" />

    <jointpos name="r_hip_z_joint_pos" joint="r_hip_z_joint" />
    <jointpos name="r_hip_x_joint_pos" joint="r_hip_x_joint" />
    <jointpos name="r_hip_y_joint_pos" joint="r_hip_y_joint" />
    <jointpos name="r_knee_y_joint_pos" joint="r_knee_y_joint" />
    <jointpos name="r_ankle_y_joint_pos" joint="r_ankle_y_joint" />
    <jointpos name="r_ankle_x_joint_pos" joint="r_ankle_x_joint" />

    <jointpos name="waist_z_joint_pos" joint="waist_z_joint" />
    <jointpos name="waist_x_joint_pos" joint="waist_x_joint" />
    <jointpos name="waist_y_joint_pos" joint="waist_y_joint" />

    <jointpos name="l_shld_y_joint_pos" joint="l_shld_y_joint" />
    <jointpos name="l_shld_x_joint_pos" joint="l_shld_x_joint" />
    <jointpos name="l_shld_z_joint_pos" joint="l_shld_z_joint" />
    <jointpos name="l_elb_y_joint_pos" joint="l_elb_y_joint" />
    <jointpos name="l_elb_z_joint_pos" joint="l_elb_z_joint" />

    <jointpos name="r_shld_y_joint_pos" joint="r_shld_y_joint" />
    <jointpos name="r_shld_x_joint_pos" joint="r_shld_x_joint" />
    <jointpos name="r_shld_z_joint_pos" joint="r_shld_z_joint" />
    <jointpos name="r_elb_y_joint_pos" joint="r_elb_y_joint" />
    <jointpos name="r_elb_z_joint_pos" joint="r_elb_z_joint" />

    <!-- joint vel sensor -->
    <jointvel name="l_hip_z_joint_vel" joint="l_hip_z_joint" />
    <jointvel name="l_hip_x_joint_vel" joint="l_hip_x_joint" />
    <jointvel name="l_hip_y_joint_vel" joint="l_hip_y_joint" />
    <jointvel name="l_knee_y_joint_vel" joint="l_knee_y_joint" />
    <jointvel name="l_ankle_y_joint_vel" joint="l_ankle_y_joint" />
    <jointvel name="l_ankle_x_joint_vel" joint="l_ankle_x_joint" />

    <jointvel name="r_hip_z_joint_vel" joint="r_hip_z_joint" />
    <jointvel name="r_hip_x_joint_vel" joint="r_hip_x_joint" />
    <jointvel name="r_hip_y_joint_vel" joint="r_hip_y_joint" />
    <jointvel name="r_knee_y_joint_vel" joint="r_knee_y_joint" />
    <jointvel name="r_ankle_y_joint_vel" joint="r_ankle_y_joint" />
    <jointvel name="r_ankle_x_joint_vel" joint="r_ankle_x_joint" />

    <jointpos name="waist_z_joint_vel" joint="waist_z_joint" />
    <jointpos name="waist_x_joint_vel" joint="waist_x_joint" />
    <jointpos name="waist_y_joint_vel" joint="waist_y_joint" />

    <jointpos name="l_shld_y_joint_vel" joint="l_shld_y_joint" />
    <jointpos name="l_shld_x_joint_vel" joint="l_shld_x_joint" />
    <jointpos name="l_shld_z_joint_vel" joint="l_shld_z_joint" />
    <jointpos name="l_elb_y_joint_vel" joint="l_elb_y_joint" />
    <jointpos name="l_elb_z_joint_vel" joint="l_elb_z_joint" />

    <jointpos name="r_shld_y_joint_vel" joint="r_shld_y_joint" />
    <jointpos name="r_shld_x_joint_vel" joint="r_shld_x_joint" />
    <jointpos name="r_shld_z_joint_vel" joint="r_shld_z_joint" />
    <jointpos name="r_elb_y_joint_vel" joint="r_elb_y_joint" />
    <jointpos name="r_elb_z_joint_vel" joint="r_elb_z_joint" />

    <touch name="lf_touch" site="lf_tc" />
    <touch name="rf_touch" site="rf_tc" />
  </sensor>


</mujoco>
