<mujoco model="trossen_ai">
  <compiler angle="radian" eulerseq="ZYX" autolimits="true"/>

  <option iterations="50" timestep="0.001" solver="Newton" gravity="0 0 -9.81" />

  <asset>
    <texture type="2d" file="assets/materials/1k_textures/trossen_BaseColor.png"/>
    <material name="trossen_material" texture="trossen_BaseColor"/>

    <mesh name="base_link" file="assets/meshes/base_link.obj" />
    <mesh name="link_1" file="assets/meshes/link_1.obj" />
    <mesh name="link_2" file="assets/meshes/link_2.obj" />
    <mesh name="link_3" file="assets/meshes/link_3.obj" />
    <mesh name="link_4" file="assets/meshes/link_4.obj" />
    <mesh name="link_5" file="assets/meshes/link_5.obj" />
    <mesh name="link_6" file="assets/meshes/link_6.obj" />
    <mesh name="carriage_left" file="assets/meshes/carriage_left.obj" />
    <mesh name="carriage_right" file="assets/meshes/carriage_right.obj" />
    <mesh name="gripper_right" file="assets/meshes/gripper_right.obj" />
    <mesh name="gripper_left" file="assets/meshes/gripper_left.obj" />
    <mesh name="camera_mount_d405" file="assets/meshes/camera_mount_d405.obj" />
    <mesh name="base_link_collision" file="assets/meshes/base_link_collision.obj" />
    <mesh name="base_link_collision.001" file="assets/meshes/base_link_collision.001.obj" />
    <mesh name="base_link_collision.002" file="assets/meshes/base_link_collision.002.obj" />
    <mesh name="base_link_collision.003" file="assets/meshes/base_link_collision.003.obj" />
    <mesh name="camera_mount_d405_collision" file="assets/meshes/camera_mount_d405_collision.obj" />
    <mesh name="camera_mount_d405_collision.001" file="assets/meshes/camera_mount_d405_collision.001.obj" />
    <mesh name="carriage_left_collision" file="assets/meshes/carriage_left_collision.obj" />
    <mesh name="carriage_right_collision" file="assets/meshes/carriage_right_collision.obj" />
    <mesh name="gripper_left_collision" file="assets/meshes/gripper_left_collision.obj" />
    <mesh name="gripper_right_collision" file="assets/meshes/gripper_right_collision.obj" />
    <mesh name="link_1_collision" file="assets/meshes/link_1_collision.obj" />
    <mesh name="link_1_collision.001" file="assets/meshes/link_1_collision.001.obj" />
    <mesh name="link_1_collision.002" file="assets/meshes/link_1_collision.002.obj" />
    <mesh name="link_1_collision.003" file="assets/meshes/link_1_collision.003.obj" />
    <mesh name="link_2_collision" file="assets/meshes/link_2_collision.obj" />
    <mesh name="link_2_collision.001" file="assets/meshes/link_2_collision.001.obj" />
    <mesh name="link_2_collision.002" file="assets/meshes/link_2_collision.002.obj" />
    <mesh name="link_2_collision.003" file="assets/meshes/link_2_collision.003.obj" />
    <mesh name="link_3_collision" file="assets/meshes/link_3_collision.obj" />
    <mesh name="link_3_collision.001" file="assets/meshes/link_3_collision.001.obj" />
    <mesh name="link_3_collision.002" file="assets/meshes/link_3_collision.002.obj" />
    <mesh name="link_3_collision.003" file="assets/meshes/link_3_collision.003.obj" />
    <mesh name="link_3_collision.004" file="assets/meshes/link_3_collision.004.obj" />
    <mesh name="link_4_collision" file="assets/meshes/link_4_collision.obj" />
    <mesh name="link_4_collision.001" file="assets/meshes/link_4_collision.001.obj" />
    <mesh name="link_4_collision.002" file="assets/meshes/link_4_collision.002.obj" />
    <mesh name="link_5_collision" file="assets/meshes/link_5_collision.obj" />
    <mesh name="link_6_collision" file="assets/meshes/link_6_collision.obj" />

  </asset>
  <default>
    <default class="wxai">
      <mesh scale="1.0 1.0 1.0"/>
      <joint axis="0 1 0" frictionloss="0.1" armature="0.1"/>
      <position kp="450" dampratio="0.95" forcerange="-55 55"/>
      <default class="visual">
        <geom type="mesh" contype="0" conaffinity="0" density="0" group="2" material="trossen_material"/>
      </default>
      <default class="collision">
        <geom group="3" type="mesh"/>
        <default class="sphere_collision">
          <geom type="sphere" size="0.0006" rgba="1 0 0 1"/>
        </default>
      </default>
    </default>

  </default>

  <worldbody>

    <camera name="teleoperator_pov" pos="0 -1.354 0.685" xyaxes="1 0 0 0 0.2 .8" fovy="53.13" resolution="640 640" mode="targetbody"/>

    <body name="left/root" pos="-0.4575 -0.019 0.02" quat="1 0 0 0" gravcomp="1">
      <geom type="mesh" rgba="0.752941 0.752941 0.752941 1" mesh="base_link" class="visual"/>
      <geom type="mesh" rgba="0.752941 0.752941 0.752941 1" mesh="base_link_collision" class="collision"/>
      <geom type="mesh" rgba="0.752941 0.752941 0.752941 1" mesh="base_link_collision.001" class="collision"/>
      <geom type="mesh" rgba="0.752941 0.752941 0.752941 1" mesh="base_link_collision.002" class="collision"/>
      <geom type="mesh" rgba="0.752941 0.752941 0.752941 1" mesh="base_link_collision.003" class="collision"/>
      <body name="left/link_1" pos="0 0 0.05725" gravcomp="1">
        <inertial pos="-0.00011075 0.00171176 0.0204459" quat="0.313955 0.305238 -0.643575 0.627752" mass="0.152704" diaginertia="0.000203432 0.000173907 8.3521e-05" />
        <joint name="left/joint_0" pos="0 0 0" axis="0 0 1" range="-3.05433 3.05433" actuatorfrcrange="-27 27" actuatorgravcomp="true"/>
        <geom type="mesh" rgba="0.752941 0.752941 0.752941 1" mesh="link_1" class="visual"/>
        <geom type="mesh" rgba="0.752941 0.752941 0.752941 1" mesh="link_1_collision" class="collision"/>
        <geom type="mesh" rgba="0.752941 0.752941 0.752941 1" mesh="link_1_collision.001" class="collision"/>
        <geom type="mesh" rgba="0.752941 0.752941 0.752941 1" mesh="link_1_collision.002" class="collision"/>
        <geom type="mesh" rgba="0.752941 0.752941 0.752941 1" mesh="link_1_collision.003" class="collision"/>
        <body name="left/link_2" pos="0.02 0 0.04625" gravcomp="1">
          <inertial pos="-0.131215 -0.00292583 0.00021345" quat="-0.00123582 0.706546 -0.00109575 0.707665" mass="1.15316" diaginertia="0.0179449 0.0173612 0.00102628" />
          <joint name="left/joint_1" pos="0 0 0" axis="0 1 0" range="0 3.14159" actuatorfrcrange="-27 27" actuatorgravcomp="true"/>
          <geom type="mesh" rgba="0.752941 0.752941 0.752941 1" mesh="link_2" class="visual"/>
          <geom type="mesh" rgba="0.752941 0.752941 0.752941 1" mesh="link_2_collision" class="collision"/>
          <geom type="mesh" rgba="0.752941 0.752941 0.752941 1" mesh="link_2_collision.001" class="collision"/>
          <geom type="mesh" rgba="0.752941 0.752941 0.752941 1" mesh="link_2_collision.002" class="collision"/>
          <geom type="mesh" rgba="0.752941 0.752941 0.752941 1" mesh="link_2_collision.003" class="collision"/>
          <body name="left/link_3" pos="-0.264 0 0" gravcomp="1">
            <inertial pos="0.180836 -0.0009409 0.0555494" quat="0.0103901 0.669684 -0.0033175 0.742566" mass="0.686666" diaginertia="0.00566898 0.00547578 0.00059316"/>
            <joint name="left/joint_2" pos="0 0 0" axis="0 -1 0" range="0.0 2.35619" actuatorfrcrange="-27 27" actuatorgravcomp="true"/>
            <geom type="mesh" rgba="0.752941 0.752941 0.752941 1" mesh="link_3" class="visual"/>
            <geom type="mesh" rgba="0.752941 0.752941 0.752941 1" mesh="link_3_collision" class="collision"/>
            <geom type="mesh" rgba="0.752941 0.752941 0.752941 1" mesh="link_3_collision.001" class="collision"/>
            <geom type="mesh" rgba="0.752941 0.752941 0.752941 1" mesh="link_3_collision.002" class="collision"/>
            <geom type="mesh" rgba="0.752941 0.752941 0.752941 1" mesh="link_3_collision.003" class="collision"/>
            <geom type="mesh" rgba="0.752941 0.752941 0.752941 1" mesh="link_3_collision.004" class="collision"/>
            <body name="left/link_4" pos="0.245 0 0.06" gravcomp="1">
              <inertial pos="0.0579784 0.00027145 0.0588445" quat="0.948688 0.0346237 0.307828 0.0635164" mass="0.457899" diaginertia="0.000670827 0.000661455 0.000288648"/>
              <joint name="left/joint_3" pos="0 0 0" axis="0 -1 0" range="-1.5708 1.5708" actuatorfrcrange="-7 7" actuatorgravcomp="true"/>
              <geom type="mesh" rgba="0.752941 0.752941 0.752941 1" mesh="link_4" class="visual"/>
              <geom type="mesh" rgba="0.752941 0.752941 0.752941 1" mesh="link_4_collision" class="collision"/>
              <geom type="mesh" rgba="0.752941 0.752941 0.752941 1" mesh="link_4_collision.001" class="collision"/>
              <geom type="mesh" rgba="0.752941 0.752941 0.752941 1" mesh="link_4_collision.002" class="collision"/>
              <body name="left/link_5" pos="0.06775 0 0.0455" gravcomp="1">
                <inertial pos="0.00412447 -1.138e-05 -0.0428318" quat="0.496144 0.502128 0.503595 0.498098" mass="0.366939" diaginertia="0.000320622 0.00026751 0.000189108" />
                <joint name="left/joint_4" pos="0 0 0" axis="0 0 -1" range="-1.5708 1.5708" actuatorfrcrange="-7 7" actuatorgravcomp="true"/>
                <geom type="mesh" rgba="0.752941 0.752941 0.752941 1" mesh="link_5" class="visual"/>
                <geom type="mesh" rgba="0.752941 0.752941 0.752941 1" mesh="link_5_collision" class="collision"/>
                <body name="left/link_6" pos="0.02895 0 -0.0455" gravcomp="1">
                  <camera name="cam_left_wrist" pos="0.06231 0.00000 0.05321" euler="-1.57 -1.22 0.0"  resolution="1920 1080" focal="1.93e-3 1.93e-3" sensorsize="0.0037 0.0021" mode="fixed"/>
                  <inertial pos="0.0470282 0.00141143 0.00922376" quat="0.274972 0.289957 -0.694213 0.598652" mass="0.673874" diaginertia="0.00139668 0.00131951 0.00100756"/>
                  <joint name="left/joint_5" pos="0 0 0" axis="1 0 0" range="-3.14159 3.14159" actuatorfrcrange="-7 7" actuatorgravcomp="true"/>
                  <geom type="mesh" rgba="0.752941 0.752941 0.752941 1" mesh="link_6" class="visual"/>
                  <geom type="mesh" rgba="0.752941 0.752941 0.752941 1" mesh="link_6_collision" class="collision"/>
                  <geom type="mesh" rgba="0.752941 0.752941 0.752941 1" mesh="camera_mount_d405" pos="0.012 0 0" class="visual"/>
                  <geom type="mesh" rgba="0.752941 0.752941 0.752941 1" mesh="camera_mount_d405_collision" pos="0.012 0 0" class="collision"/>
                  <geom type="mesh" rgba="0.752941 0.752941 0.752941 1" mesh="camera_mount_d405_collision.001" pos="0.012 0 0" class="collision"/>
                  <geom size="0.0115 0.021 0.021" pos="0.0393206 0 0.0569399" quat="0.984808 0 0.173648 0" type="box" class="visual"/>
                  <geom type="box" rgba="" size="0.0115 0.021 0.021" pos="0.0393206 0 0.0569399" quat="0.984808 0 0.173648 0" />
                  <body name="left/carriage_right" pos="0.0865 -0.023 0" gravcomp="1">
                    <inertial pos="0.00169015 0.00592793 0.00201817" quat="-0.370973 0.740886 -0.0847721 0.553427" mass="0.081271" diaginertia="4.29565e-05 3.87081e-05 2.21528e-05" />
                    <joint name="left/right_carriage_joint" pos="0 0 0" axis="0 -1 0" type="slide" range="0 0.044" actuatorfrcrange="-400 400" actuatorgravcomp="true" stiffness="50" />
                    <site name="left/carriage_site" pos="0.065 0.0225 0" size="0.01" type="sphere" rgba="1 0 0 1" group="5"/>
                    <geom type="mesh" rgba="0.752941 0.752941 0.752941 1" mesh="carriage_right" class="visual"/>
                    <geom type="mesh" rgba="0.752941 0.752941 0.752941 1" mesh="carriage_right_collision" class="collision"/>
                    <geom type="mesh" rgba="0.752941 0.752941 0.752941 1" mesh="gripper_right" class="visual"/>
                    <geom name="left/gripper_follower_right" type="mesh" rgba="0.752941 0.752941 0.752941 1"  mesh="gripper_right_collision" class="collision" friction="2.0 0.02 0.01" condim="4" solimp="0.95 0.95 0.001" solref="0.005 1"/>
                  </body>
                  <body name="left/carriage_left" pos="0.0865 0.023 0" gravcomp="1">
                    <inertial pos="0.00169017 -0.00592796 -0.00365701" quat="-0.0382691 0.628022 -0.255101 0.734198" mass="0.081271" diaginertia="4.21112e-05 3.61943e-05 2.40003e-05" />
                    <joint name="left/left_carriage_joint" pos="0 0 0" axis="0 1 0" type="slide" range="0 0.044" actuatorfrcrange="-400 400" actuatorgravcomp="true" stiffness="50" />
                    <geom type="mesh" rgba="0.752941 0.752941 0.752941 1" mesh="carriage_left" class="visual"/>
                    <geom type="mesh" rgba="0.752941 0.752941 0.752941 1" mesh="carriage_left_collision" class="collision"/>
                    <geom type="mesh" rgba="0.752941 0.752941 0.752941 1" mesh="gripper_left" class="visual"/>
                    <geom name ="left/gripper_follower_left" type="mesh" rgba="0.752941 0.752941 0.752941 1"  mesh="gripper_left_collision" class="collision" friction="2.0 0.02 0.01" condim="4" solimp="0.95 0.95 0.001" solref="0.005 1"/>
                  </body>
                </body>
              </body>
            </body>
          </body>
        </body>
      </body>
    </body>

    <body name="right/root" pos="0.4575 -0.019 0.02" quat="0 0 0 1" gravcomp="1">
      <geom type="mesh" rgba="0.752941 0.752941 0.752941 1" mesh="base_link" class="visual"/>
      <geom type="mesh" rgba="0.752941 0.752941 0.752941 1" mesh="base_link_collision" class="collision"/>
      <geom type="mesh" rgba="0.752941 0.752941 0.752941 1" mesh="base_link_collision.001" class="collision"/>
      <geom type="mesh" rgba="0.752941 0.752941 0.752941 1" mesh="base_link_collision.002" class="collision"/>
      <geom type="mesh" rgba="0.752941 0.752941 0.752941 1" mesh="base_link_collision.003" class="collision"/>
      <body name="right/link_1" pos="0 0 0.05725" gravcomp="1">
        <inertial pos="-0.00011075 0.00171176 0.0204459" quat="0.313955 0.305238 -0.643575 0.627752" mass="0.152704" diaginertia="0.000203432 0.000173907 8.3521e-05" />
        <joint name="right/joint_0" pos="0 0 0" axis="0 0 1" range="-3.05433 3.05433" actuatorfrcrange="-27 27" actuatorgravcomp="true"/>
        <geom type="mesh" rgba="0.752941 0.752941 0.752941 1" mesh="link_1" class="visual"/>
        <geom type="mesh" rgba="0.752941 0.752941 0.752941 1" mesh="link_1_collision" class="collision"/>
        <geom type="mesh" rgba="0.752941 0.752941 0.752941 1" mesh="link_1_collision.001" class="collision"/>
        <geom type="mesh" rgba="0.752941 0.752941 0.752941 1" mesh="link_1_collision.002" class="collision"/>
        <geom type="mesh" rgba="0.752941 0.752941 0.752941 1" mesh="link_1_collision.003" class="collision"/>
        <body name="right/link_2" pos="0.02 0 0.04625" gravcomp="1">
          <inertial pos="-0.131215 -0.00292583 0.00021345" quat="-0.00123582 0.706546 -0.00109575 0.707665" mass="1.15316" diaginertia="0.0179449 0.0173612 0.00102628" />
          <joint name="right/joint_1" pos="0 0 0" axis="0 1 0" range="0 3.14159" actuatorfrcrange="-27 27" actuatorgravcomp="true" />
          <geom type="mesh" rgba="0.752941 0.752941 0.752941 1" mesh="link_2" class="visual"/>
          <geom type="mesh" rgba="0.752941 0.752941 0.752941 1" mesh="link_2_collision" class="collision"/>
          <geom type="mesh" rgba="0.752941 0.752941 0.752941 1" mesh="link_2_collision.001" class="collision"/>
          <geom type="mesh" rgba="0.752941 0.752941 0.752941 1" mesh="link_2_collision.002" class="collision"/>
          <geom type="mesh" rgba="0.752941 0.752941 0.752941 1" mesh="link_2_collision.003" class="collision"/>
          <body name="right/link_3" pos="-0.264 0 0" gravcomp="1">
            <inertial pos="0.180836 -0.0009409 0.0555494" quat="0.0103901 0.669684 -0.0033175 0.742566" mass="0.686666" diaginertia="0.00566898 0.00547578 0.00059316"/>
            <joint name="right/joint_2" pos="0 0 0" axis="0 -1 0" range="0.0 2.35619" actuatorfrcrange="-27 27" actuatorgravcomp="true"/>
            <geom type="mesh" rgba="0.752941 0.752941 0.752941 1" mesh="link_3" class="visual"/>
            <geom type="mesh" rgba="0.752941 0.752941 0.752941 1" mesh="link_3_collision" class="collision"/>
            <geom type="mesh" rgba="0.752941 0.752941 0.752941 1" mesh="link_3_collision.001" class="collision"/>
            <geom type="mesh" rgba="0.752941 0.752941 0.752941 1" mesh="link_3_collision.002" class="collision"/>
            <geom type="mesh" rgba="0.752941 0.752941 0.752941 1" mesh="link_3_collision.003" class="collision"/>
            <geom type="mesh" rgba="0.752941 0.752941 0.752941 1" mesh="link_3_collision.004" class="collision"/>
            <body name="right/link_4" pos="0.245 0 0.06" gravcomp="1">
              <inertial pos="0.0579784 0.00027145 0.0588445" quat="0.948688 0.0346237 0.307828 0.0635164" mass="0.457899" diaginertia="0.000670827 0.000661455 0.000288648"/>
              <joint name="right/joint_3" pos="0 0 0" axis="0 -1 0" range="-1.5708 1.5708" actuatorfrcrange="-7 7" actuatorgravcomp="true"/>
              <geom type="mesh" rgba="0.752941 0.752941 0.752941 1" mesh="link_4" class="visual"/>
              <geom type="mesh" rgba="0.752941 0.752941 0.752941 1" mesh="link_4_collision" class="collision"/>
              <geom type="mesh" rgba="0.752941 0.752941 0.752941 1" mesh="link_4_collision.001" class="collision"/>
              <geom type="mesh" rgba="0.752941 0.752941 0.752941 1" mesh="link_4_collision.002" class="collision"/>
              <body name="right/link_5" pos="0.06775 0 0.0455" gravcomp="1">
                <inertial pos="0.00412447 -1.138e-05 -0.0428318" quat="0.496144 0.502128 0.503595 0.498098" mass="0.366939" diaginertia="0.000320622 0.00026751 0.000189108" />
                <joint name="right/joint_4" pos="0 0 0" axis="0 0 -1" range="-1.5708 1.5708" actuatorfrcrange="-7 7" actuatorgravcomp="true"/>
                <geom type="mesh" rgba="0.752941 0.752941 0.752941 1" mesh="link_5" class="visual"/>
                <geom type="mesh" rgba="0.752941 0.752941 0.752941 1" mesh="link_5_collision" class="collision"/>
                <body name="right/link_6" pos="0.02895 0 -0.0455" gravcomp="1">
                  <camera name="cam_right_wrist" pos="0.06231 0.00000 0.05321" euler="-1.57 -1.22 0.0"  resolution="1920 1080" focal="1.93e-3 1.93e-3" sensorsize="0.0037 0.0021" mode="fixed"/>
                  <inertial pos="0.0470282 0.00141143 0.00922376" quat="0.274972 0.289957 -0.694213 0.598652" mass="0.673874" diaginertia="0.00139668 0.00131951 0.00100756"/>
                  <joint name="right/joint_5" pos="0 0 0" axis="1 0 0" range="-3.14159 3.14159" actuatorfrcrange="-7 7" actuatorgravcomp="true"/>
                  <geom type="mesh" rgba="0.752941 0.752941 0.752941 1" mesh="link_6" class="visual"/>
                  <geom type="mesh" rgba="0.752941 0.752941 0.752941 1" mesh="link_6_collision" class="collision"/>
                  <geom type="mesh" rgba="0.752941 0.752941 0.752941 1" mesh="camera_mount_d405" pos="0.012 0 0" class="visual"/>
                  <geom type="mesh" rgba="0.752941 0.752941 0.752941 1" mesh="camera_mount_d405_collision" pos="0.012 0 0" class="collision"/>
                  <geom type="mesh" rgba="0.752941 0.752941 0.752941 1" mesh="camera_mount_d405_collision.001" pos="0.012 0 0" class="collision"/>
                  <geom size="0.0115 0.021 0.021" pos="0.0393206 0 0.0569399" quat="0.984808 0 0.173648 0" type="box" class="visual"/>
                  <geom type="box" rgba="" size="0.0115 0.021 0.021" pos="0.0393206 0 0.0569399" quat="0.984808 0 0.173648 0" />
                  <body name="right/carriage_right" pos="0.0865 -0.023 0" gravcomp="1">
                    <inertial pos="0.00169015 0.00592793 0.00201817" quat="-0.370973 0.740886 -0.0847721 0.553427" mass="0.081271" diaginertia="4.29565e-05 3.87081e-05 2.21528e-05" />
                    <joint name="right/right_carriage_joint" pos="0 0 0" axis="0 -1 0" type="slide" range="0 0.044" actuatorfrcrange="-400 400" actuatorgravcomp="true" stiffness="50" />
                    <site name="right/carriage_site" pos="0.065 0.0225 0" size="0.01" type="sphere" rgba="1 0 0 1" group="5"/>
                    <geom type="mesh" rgba="0.752941 0.752941 0.752941 1" mesh="carriage_right" class="visual"/>
                    <geom type="mesh" rgba="0.752941 0.752941 0.752941 1" mesh="carriage_right_collision" class="collision"/>
                    <geom type="mesh" rgba="0.752941 0.752941 0.752941 1" mesh="gripper_right" class="visual"/>
                    <geom name= "right/gripper_follower_right" type="mesh" rgba="0.752941 0.752941 0.752941 1"  mesh="gripper_right_collision" class="collision" friction="2.0 0.02 0.01" condim="4" solimp="0.95 0.95 0.001" solref="0.005 1" />
                  </body>
                  <body name="right/carriage_left" pos="0.0865 0.023 0" gravcomp="1">
                    <inertial pos="0.00169017 -0.00592796 -0.00365701" quat="-0.0382691 0.628022 -0.255101 0.734198" mass="0.081271" diaginertia="4.21112e-05 3.61943e-05 2.40003e-05" />
                    <joint name="right/left_carriage_joint" pos="0 0 0" axis="0 1 0" type="slide" range="0 0.044" actuatorfrcrange="-400 400" actuatorgravcomp="true" stiffness="50" />
                    <geom type="mesh" rgba="0.752941 0.752941 0.752941 1" mesh="carriage_left" class="visual"/>
                    <geom type="mesh" rgba="0.752941 0.752941 0.752941 1" mesh="carriage_left_collision" class="collision"/>
                    <geom type="mesh" rgba="0.752941 0.752941 0.752941 1" mesh="gripper_left" class="visual"/>
                    <geom name="right/gripper_follower_left" type="mesh" rgba="0.752941 0.752941 0.752941 1"  mesh="gripper_left_collision" class="collision" friction="2.0 0.02 0.01" condim="4" solimp="0.95 0.95 0.001" solref="0.005 1" />
                  </body>
                </body>
              </body>
            </body>
          </body>
        </body>
      </body>
    </body>
  </worldbody>

  <contact>
    <exclude body1="left/root" body2="left/link_1"/>
    <exclude body1="right/root" body2="right/link_1"/>
    <exclude body1="left/carriage_left" body2="left/carriage_right"/>
    <exclude body1="right/carriage_left" body2="right/carriage_right"/>

  </contact>

  <actuator>
    <position name="left/joint_0" joint="left/joint_0" class="wxai" ctrllimited="true" ctrlrange="-1.0 1.0"/>
    <position name="left/joint_1" joint="left/joint_1" class="wxai" ctrllimited="true" ctrlrange="-1.0 1.0"/>
    <position name="left/joint_2" joint="left/joint_2" class="wxai" ctrllimited="true" ctrlrange="-1.0 1.0"/>
    <position name="left/joint_3" joint="left/joint_3" class="wxai" ctrllimited="true" ctrlrange="-1.0 1.0"/>
    <position name="left/joint_4" joint="left/joint_4" class="wxai" ctrllimited="true" ctrlrange="-1.0 1.0"/>
    <position name="left/joint_5" joint="left/joint_5" class="wxai" ctrllimited="true" ctrlrange="-1.0 1.0"/>
    <position name="left/joint_gl" joint="left/left_carriage_joint" class="wxai" ctrllimited="true" ctrlrange="-1.0 1.0"/>
    <position name="left/joint_gr" joint="left/right_carriage_joint" class="wxai" ctrllimited="true" ctrlrange="-1.0 1.0"/>


    <position name="right/joint_0" joint="right/joint_0" class="wxai" ctrllimited="true" ctrlrange="-1.0 1.0"/>
    <position name="right/joint_1" joint="right/joint_1" class="wxai" ctrllimited="true" ctrlrange="-1.0 1.0"/>
    <position name="right/joint_2" joint="right/joint_2" class="wxai" ctrllimited="true" ctrlrange="-1.0 1.0"/>
    <position name="right/joint_3" joint="right/joint_3" class="wxai" ctrllimited="true" ctrlrange="-1.0 1.0"/>
    <position name="right/joint_4" joint="right/joint_4" class="wxai" ctrllimited="true" ctrlrange="-1.0 1.0"/>
    <position name="right/joint_5" joint="right/joint_5" class="wxai" ctrllimited="true" ctrlrange="-1.0 1.0"/>
    <position name="right/joint_gl" joint="right/left_carriage_joint" class="wxai" ctrllimited="true" ctrlrange="-1.0 1.0"/>
    <position name="right/joint_gr" joint="right/right_carriage_joint" class="wxai" ctrllimited="true" ctrlrange="-1.0 1.0"/>

  </actuator>

</mujoco>
