<?xml version="1.0" ?>
<robot name="toddlerbot_2xm">
  <mujoco>
    <compiler strippath="false" balanceinertia="true" discardvisual="false"/>
  </mujoco>
  <link name="world">
    <inertial>
      <origin xyz="0.0 0.0 0.0" rpy="0.0 0.0 0.0"/>
      <mass value="0.0"/>
      <inertia ixx="0.0" iyy="0.0" izz="0.0" ixy="0" ixz="0" iyz="0"/>
    </inertial>
  </link>
  <link name="torso">
    <inertial>
      <origin xyz="-0.0194013 -0.00385148 0.0614411" rpy="-0.696046 0.0702126 0.11645"/>
      <mass value="1.27503"/>
      <inertia ixx="0.003412958325793508" iyy="0.0027421698674606654" izz="0.002637641806745822" ixy="0" ixz="0" iyz="0"/>
    </inertial>
    <visual name="torso_visual">
      <origin xyz="-0.0194013 -0.00385148 0.0614411" rpy="0.0 0.0 0.0"/>
      <geometry>
        <mesh filename="assets/torso_visual.stl" scale="1.0 1.0 1.0"/>
      </geometry>
      <material name="torso_visual_material"/>
    </visual>
    <collision name="torso_collision_0">
      <origin xyz="-0.025508 0.0 0.06" rpy="0.0 0.0 0.0"/>
      <geometry>
        <box type="box" size="0.09 0.13 0.12"/>
      </geometry>
    </collision>
    <collision name="torso_collision_1">
      <origin xyz="-0.093008 0.0 0.01425" rpy="0.0 0.0 0.0"/>
      <geometry>
        <box type="box" size="0.045 0.0285 0.0285"/>
      </geometry>
    </collision>
  </link>
  <link name="torso_freejoint_body">
    <inertial>
      <origin xyz="0.0 0.0 0.0" rpy="0.0 0.0 0.0"/>
      <mass value="0.001"/>
      <inertia ixx="1e-09" iyy="1e-09" izz="1e-09" ixy="0" ixz="0" iyz="0"/>
    </inertial>
  </link>
  <joint type="floating" name="torso_freejoint">
    <parent link="world"/>
    <child link="torso_freejoint_body"/>
    <origin xyz="0.0 0.0 0.315053" rpy="0.0 0.0 0.0"/>
    <limit lower="-999999" upper="999999" effort="1000" velocity="1000"/>
  </joint>
  <joint type="fixed" name="torso_freejoint_offset">
    <parent link="torso_freejoint_body"/>
    <child link="torso"/>
    <origin xyz="0.0 0.0 0.0" rpy="0.0 0.0 0.0"/>
  </joint>
  <link name="neck_yaw_gear_drive">
    <inertial>
      <origin xyz="0.0 0.0 0.0033841" rpy="1.5708 -1.5708 0.0"/>
      <mass value="0.003"/>
      <inertia ixx="1.55295e-07" iyy="8.71388e-08" izz="8.71388e-08" ixy="0" ixz="0" iyz="0"/>
    </inertial>
    <visual name="neck_yaw_gear_drive_visual">
      <origin xyz="0.0 0.0 0.0033841" rpy="0.0 0.0 0.0"/>
      <geometry>
        <mesh filename="assets/neck_yaw_gear_drive_visual.stl" scale="1.0 1.0 1.0"/>
      </geometry>
      <material name="neck_yaw_gear_drive_visual_material"/>
    </visual>
  </link>
  <link name="neck_yaw_drive_body">
    <inertial>
      <origin xyz="0.0 0.0 0.0" rpy="0.0 0.0 0.0"/>
      <mass value="0.001"/>
      <inertia ixx="1e-09" iyy="1e-09" izz="1e-09" ixy="0" ixz="0" iyz="0"/>
    </inertial>
  </link>
  <joint type="fixed" name="neck_yaw_drive">
    <parent link="torso"/>
    <child link="neck_yaw_drive_body"/>
    <origin xyz="-0.0215079 0.0 0.119" rpy="0.0 0.0 0.0"/>
  </joint>
  <joint type="fixed" name="neck_yaw_drive_offset">
    <parent link="neck_yaw_drive_body"/>
    <child link="neck_yaw_gear_drive"/>
    <origin xyz="0.0 0.0 0.0" rpy="0.0 0.0 0.0"/>
  </joint>
  <link name="neck_yaw_link">
    <inertial>
      <origin xyz="-3.41e-06 0.0 0.00821562" rpy="-0.0150909 0.0 1.5708"/>
      <mass value="0.006"/>
      <inertia ixx="6.2064e-07" iyy="4.777318598148802e-07" izz="3.2903914018512e-07" ixy="0" ixz="0" iyz="0"/>
    </inertial>
    <visual name="neck_yaw_link_visual">
      <origin xyz="-3.41e-06 0.0 0.00821562" rpy="0.0 0.0 0.0"/>
      <geometry>
        <mesh filename="assets/neck_yaw_link_visual.stl" scale="1.0 1.0 1.0"/>
      </geometry>
      <material name="neck_yaw_link_visual_material"/>
    </visual>
  </link>
  <link name="neck_yaw_driven_body">
    <inertial>
      <origin xyz="0.0 0.0 0.0" rpy="0.0 0.0 0.0"/>
      <mass value="0.001"/>
      <inertia ixx="1e-09" iyy="1e-09" izz="1e-09" ixy="0" ixz="0" iyz="0"/>
    </inertial>
  </link>
  <joint type="revolute" name="neck_yaw_driven">
    <parent link="torso"/>
    <child link="neck_yaw_driven_body"/>
    <origin xyz="-0.00050787 0.0 0.124" rpy="0.0 0.0 0.0"/>
    <axis xyz="0.0 0.0 1.0"/>
    <limit lower="-2.6179938779914944" upper="2.6179938779914944" effort="100" velocity="100"/>
  </joint>
  <joint type="fixed" name="neck_yaw_driven_offset">
    <parent link="neck_yaw_driven_body"/>
    <child link="neck_yaw_link"/>
    <origin xyz="0.0 0.0 0.0" rpy="0.0 0.0 0.0"/>
  </joint>
  <link name="head">
    <inertial>
      <origin xyz="-0.0104852 0.00111009 0.0447856" rpy="-0.523779 0.0532002 1.54487"/>
      <mass value="0.143321"/>
      <inertia ixx="0.00012202103620349928" iyy="0.00011484347868761218" izz="9.015538510888832e-05" ixy="0" ixz="0" iyz="0"/>
    </inertial>
    <visual name="head_visual">
      <origin xyz="-0.0104852 0.00111009 0.0447856" rpy="0.0 0.0 0.0"/>
      <geometry>
        <mesh filename="assets/head_visual.stl" scale="1.0 1.0 1.0"/>
      </geometry>
      <material name="head_visual_material"/>
    </visual>
    <collision name="head_collision">
      <origin xyz="-0.0105 -0.0035 0.046416" rpy="0.0 0.0 0.0"/>
      <geometry>
        <box type="box" size="0.07 0.084 0.06"/>
      </geometry>
    </collision>
  </link>
  <link name="neck_pitch_body">
    <inertial>
      <origin xyz="0.0 0.0 0.0" rpy="0.0 0.0 0.0"/>
      <mass value="0.001"/>
      <inertia ixx="1e-09" iyy="1e-09" izz="1e-09" ixy="0" ixz="0" iyz="0"/>
    </inertial>
  </link>
  <joint type="revolute" name="neck_pitch">
    <parent link="neck_yaw_link"/>
    <child link="neck_pitch_body"/>
    <origin xyz="0.0 0.004 0.015" rpy="0.0 0.0 0.0"/>
    <axis xyz="0.0 1.0 0.0"/>
    <limit lower="-0.6108652381980779" upper="1.396263401595401" effort="100" velocity="100"/>
  </joint>
  <joint type="fixed" name="neck_pitch_offset">
    <parent link="neck_pitch_body"/>
    <child link="head"/>
    <origin xyz="0.0 0.0 0.0" rpy="0.0 0.0 0.0"/>
  </joint>
  <link name="neck_pitch_plate">
    <inertial>
      <origin xyz="0.0 -0.00282818 0.0" rpy="1.83622 -1.5708 0.0"/>
      <mass value="0.002"/>
      <inertia ixx="1.08464e-07" iyy="6.126017302052663e-08" izz="5.619012697947335e-08" ixy="0" ixz="0" iyz="0"/>
    </inertial>
    <visual name="neck_pitch_plate_visual">
      <origin xyz="0.0 -0.00282818 0.0" rpy="0.0 0.0 0.0"/>
      <geometry>
        <mesh filename="assets/neck_pitch_plate_visual.stl" scale="1.0 1.0 1.0"/>
      </geometry>
      <material name="neck_pitch_plate_visual_material"/>
    </visual>
  </link>
  <link name="neck_pitch_act_body">
    <inertial>
      <origin xyz="0.0 0.0 0.0" rpy="0.0 0.0 0.0"/>
      <mass value="0.001"/>
      <inertia ixx="1e-09" iyy="1e-09" izz="1e-09" ixy="0" ixz="0" iyz="0"/>
    </inertial>
  </link>
  <joint type="fixed" name="neck_pitch_act">
    <parent link="head"/>
    <child link="neck_pitch_act_body"/>
    <origin xyz="-0.027 -0.0025 0.0326157" rpy="0.0 0.0 0.0"/>
  </joint>
  <joint type="fixed" name="neck_pitch_act_offset">
    <parent link="neck_pitch_act_body"/>
    <child link="neck_pitch_plate"/>
    <origin xyz="0.0 0.0 0.0" rpy="0.0 0.0 0.0"/>
  </joint>
  <link name="neck_rod">
    <inertial>
      <origin xyz="0.0134812 -0.00159086 -0.0163176" rpy="1.57129 -1.5708 0.0"/>
      <mass value="0.00297389"/>
      <inertia ixx="9.687779999999995e-07" iyy="9.56038228161363e-07" izz="1.7271171838636787e-08" ixy="0" ixz="0" iyz="0"/>
    </inertial>
    <visual name="neck_rod_visual">
      <origin xyz="0.0134812 -0.00159086 -0.0163176" rpy="0.0 9.2e-07 0.0"/>
      <geometry>
        <mesh filename="assets/neck_rod_visual.stl" scale="1.0 1.0 1.0"/>
      </geometry>
      <material name="neck_rod_visual_material"/>
    </visual>
  </link>
  <link name="neck_pitch_front_body">
    <inertial>
      <origin xyz="0.0 0.0 0.0" rpy="0.0 0.0 0.0"/>
      <mass value="0.001"/>
      <inertia ixx="1e-09" iyy="1e-09" izz="1e-09" ixy="0" ixz="0" iyz="0"/>
    </inertial>
  </link>
  <joint type="fixed" name="neck_pitch_front">
    <parent link="neck_pitch_plate"/>
    <child link="neck_pitch_front_body"/>
    <origin xyz="0.00723736 -0.0055 0.0019674" rpy="0.0 0.0 0.0"/>
  </joint>
  <joint type="fixed" name="neck_pitch_front_offset">
    <parent link="neck_pitch_front_body"/>
    <child link="neck_rod"/>
    <origin xyz="0.0 0.0 0.0" rpy="0.0 0.0 0.0"/>
  </joint>
  <link name="neck_rod_2">
    <inertial>
      <origin xyz="0.0134868 -0.00159086 -0.0163025" rpy="1.5712 -1.5708 0.0"/>
      <mass value="0.00297389"/>
      <inertia ixx="9.67757e-07" iyy="9.550171535837197e-07" izz="1.7270946416280333e-08" ixy="0" ixz="0" iyz="0"/>
    </inertial>
    <visual name="neck_rod_2_visual">
      <origin xyz="0.0134868 -0.00159086 -0.0163025" rpy="0.0 5.2e-07 0.0"/>
      <geometry>
        <mesh filename="assets/neck_rod_2_visual.stl" scale="1.0 1.0 1.0"/>
      </geometry>
      <material name="neck_rod_2_visual_material"/>
    </visual>
  </link>
  <link name="neck_pitch_back_body">
    <inertial>
      <origin xyz="0.0 0.0 0.0" rpy="0.0 0.0 0.0"/>
      <mass value="0.001"/>
      <inertia ixx="1e-09" iyy="1e-09" izz="1e-09" ixy="0" ixz="0" iyz="0"/>
    </inertial>
  </link>
  <joint type="fixed" name="neck_pitch_back">
    <parent link="neck_pitch_plate"/>
    <child link="neck_pitch_back_body"/>
    <origin xyz="-0.00723736 -0.0055 -0.0019674" rpy="0.0 0.0 0.0"/>
  </joint>
  <joint type="fixed" name="neck_pitch_back_offset">
    <parent link="neck_pitch_back_body"/>
    <child link="neck_rod_2"/>
    <origin xyz="0.0 0.0 0.0" rpy="0.0 0.0 0.0"/>
  </joint>
  <link name="waist_gears">
    <inertial>
      <origin xyz="0.0 0.0 -0.0129916" rpy="1.5708 3.81109e-06 1.5708"/>
      <mass value="0.0371617"/>
      <inertia ixx="1.1906300000004848e-05" iyy="1.1572599999995153e-05" izz="2.6567e-06" ixy="0" ixz="0" iyz="0"/>
    </inertial>
    <visual name="waist_gears_visual">
      <origin xyz="0.0 0.0 -0.0129916" rpy="0.0 0.0 0.0"/>
      <geometry>
        <mesh filename="assets/waist_gears_visual.stl" scale="1.0 1.0 1.0"/>
      </geometry>
      <material name="waist_gears_visual_material"/>
    </visual>
  </link>
  <link name="waist_yaw_body">
    <inertial>
      <origin xyz="0.0 0.0 0.0" rpy="0.0 0.0 0.0"/>
      <mass value="0.001"/>
      <inertia ixx="1e-09" iyy="1e-09" izz="1e-09" ixy="0" ixz="0" iyz="0"/>
    </inertial>
  </link>
  <joint type="revolute" name="waist_yaw">
    <parent link="torso"/>
    <child link="waist_yaw_body"/>
    <origin xyz="-0.0165079 0.0 -0.00248651" rpy="0.0 0.0 0.0"/>
    <axis xyz="0.0 0.0 1.0"/>
    <limit lower="-1.570796326794894" upper="1.5707963267948992" effort="100" velocity="100"/>
  </joint>
  <joint type="fixed" name="waist_yaw_offset">
    <parent link="waist_yaw_body"/>
    <child link="waist_gears"/>
    <origin xyz="0.0 0.0 0.0" rpy="0.0 0.0 0.0"/>
  </joint>
  <link name="pelvis_link">
    <inertial>
      <origin xyz="-0.0231545 0.0 -0.0260806" rpy="1.57054 -0.0185878 1.5708"/>
      <mass value="0.1052"/>
      <inertia ixx="9.14431991849157e-05" iyy="6.742020227196802e-05" izz="4.570519854311625e-05" ixy="0" ixz="0" iyz="0"/>
    </inertial>
    <visual name="pelvis_link_visual">
      <origin xyz="-0.0231545 0.0 -0.0260806" rpy="0.0 0.0 0.0"/>
      <geometry>
        <mesh filename="assets/pelvis_link_visual.stl" scale="1.0 1.0 1.0"/>
      </geometry>
      <material name="pelvis_link_visual_material"/>
    </visual>
    <collision name="pelvis_link_collision">
      <origin xyz="-0.02275 0.0 -0.035346" rpy="0.0 0.0 0.0"/>
      <geometry>
        <box type="box" size="0.07 0.12 0.044338"/>
      </geometry>
    </collision>
  </link>
  <link name="waist_roll_body">
    <inertial>
      <origin xyz="0.0 0.0 0.0" rpy="0.0 0.0 0.0"/>
      <mass value="0.001"/>
      <inertia ixx="1e-09" iyy="1e-09" izz="1e-09" ixy="0" ixz="0" iyz="0"/>
    </inertial>
  </link>
  <joint type="revolute" name="waist_roll">
    <parent link="waist_gears"/>
    <child link="waist_roll_body"/>
    <origin xyz="0.0230079 0.0 -0.014" rpy="0.0 0.0 0.0"/>
    <axis xyz="1.0 0.0 0.0"/>
    <limit lower="-0.5235987755983006" upper="0.523598775598297" effort="100" velocity="100"/>
  </joint>
  <joint type="fixed" name="waist_roll_offset">
    <parent link="waist_roll_body"/>
    <child link="pelvis_link"/>
    <origin xyz="0.0 0.0 0.0" rpy="0.0 0.0 0.0"/>
  </joint>
  <link name="waist_gear_drive">
    <inertial>
      <origin xyz="0.0 0.0 0.00671824" rpy="1.5708 -1.5708 0.0"/>
      <mass value="0.002"/>
      <inertia ixx="3.95436e-08" iyy="3.70258e-08" izz="3.70258e-08" ixy="0" ixz="0" iyz="0"/>
    </inertial>
    <visual name="waist_gear_drive_visual">
      <origin xyz="0.0 0.0 0.00671824" rpy="0.0 0.0 0.0"/>
      <geometry>
        <mesh filename="assets/waist_gear_drive_visual.stl" scale="1.0 1.0 1.0"/>
      </geometry>
      <material name="waist_gear_drive_visual_material"/>
    </visual>
  </link>
  <link name="waist_act_1_body">
    <inertial>
      <origin xyz="0.0 0.0 0.0" rpy="0.0 0.0 0.0"/>
      <mass value="0.001"/>
      <inertia ixx="1e-09" iyy="1e-09" izz="1e-09" ixy="0" ixz="0" iyz="0"/>
    </inertial>
  </link>
  <joint type="fixed" name="waist_act_1">
    <parent link="pelvis_link"/>
    <child link="waist_act_1_body"/>
    <origin xyz="-0.01275 0.0 -0.0196" rpy="0.0 0.0 0.0"/>
  </joint>
  <joint type="fixed" name="waist_act_1_offset">
    <parent link="waist_act_1_body"/>
    <child link="waist_gear_drive"/>
    <origin xyz="0.0 0.0 0.0" rpy="0.0 0.0 0.0"/>
  </joint>
  <link name="waist_gear_drive_2">
    <inertial>
      <origin xyz="0.0 0.0 0.00671824" rpy="1.5708 -1.5708 0.0"/>
      <mass value="0.002"/>
      <inertia ixx="3.95436e-08" iyy="3.70258e-08" izz="3.70258e-08" ixy="0" ixz="0" iyz="0"/>
    </inertial>
    <visual name="waist_gear_drive_2_visual">
      <origin xyz="0.0 0.0 0.00671824" rpy="0.0 0.0 1e-07"/>
      <geometry>
        <mesh filename="assets/waist_gear_drive_2_visual.stl" scale="1.0 1.0 1.0"/>
      </geometry>
      <material name="waist_gear_drive_2_visual_material"/>
    </visual>
  </link>
  <link name="waist_act_2_body">
    <inertial>
      <origin xyz="0.0 0.0 0.0" rpy="0.0 0.0 0.0"/>
      <mass value="0.001"/>
      <inertia ixx="1e-09" iyy="1e-09" izz="1e-09" ixy="0" ixz="0" iyz="0"/>
    </inertial>
  </link>
  <joint type="fixed" name="waist_act_2">
    <parent link="pelvis_link"/>
    <child link="waist_act_2_body"/>
    <origin xyz="-0.03275 0.0 -0.0196" rpy="0.0 0.0 0.0"/>
  </joint>
  <joint type="fixed" name="waist_act_2_offset">
    <parent link="waist_act_2_body"/>
    <child link="waist_gear_drive_2"/>
    <origin xyz="0.0 0.0 0.0" rpy="0.0 0.0 0.0"/>
  </joint>
  <link name="left_hip_pitch_link">
    <inertial>
      <origin xyz="-0.0203085 0.0188253 -0.0117862" rpy="1.57609 -0.00223222 1.56256"/>
      <mass value="0.188221"/>
      <inertia ixx="0.000131417575673231" iyy="0.00011438871462386323" izz="5.023340970290578e-05" ixy="0" ixz="0" iyz="0"/>
    </inertial>
    <visual name="left_hip_pitch_link_visual">
      <origin xyz="-0.0203085 0.0188253 -0.0117862" rpy="0.0 0.0 0.0"/>
      <geometry>
        <mesh filename="assets/left_hip_pitch_link_visual.stl" scale="1.0 1.0 1.0"/>
      </geometry>
      <material name="hip_pitch_link_visual_material"/>
    </visual>
    <collision name="left_hip_pitch_link_collision">
      <origin xyz="-0.01805 0.0168 -0.012" rpy="0.0 0.0 0.0"/>
      <geometry>
        <box type="box" size="0.0859 0.0424 0.0465"/>
      </geometry>
    </collision>
  </link>
  <link name="left_hip_pitch_body">
    <inertial>
      <origin xyz="0.0 0.0 0.0" rpy="0.0 0.0 0.0"/>
      <mass value="0.001"/>
      <inertia ixx="1e-09" iyy="1e-09" izz="1e-09" ixy="0" ixz="0" iyz="0"/>
    </inertial>
  </link>
  <joint type="revolute" name="left_hip_pitch">
    <parent link="pelvis_link"/>
    <child link="left_hip_pitch_body"/>
    <origin xyz="-0.02275 0.018 -0.0481" rpy="0.0 0.0 0.0"/>
    <axis xyz="0.0 1.0 0.0"/>
    <limit lower="-2.356194490192345" upper="0.7853981633974483" effort="100" velocity="100"/>
  </joint>
  <joint type="fixed" name="left_hip_pitch_offset">
    <parent link="left_hip_pitch_body"/>
    <child link="left_hip_pitch_link"/>
    <origin xyz="0.0 0.0 0.0" rpy="0.0 0.0 0.0"/>
  </joint>
  <link name="left_hip_roll_link">
    <inertial>
      <origin xyz="0.0246449 -3.22e-06 -0.0172318" rpy="0.0190768 -0.000313585 0.000387817"/>
      <mass value="0.022"/>
      <inertia ixx="9.951740710603494e-06" iyy="8.778876227225876e-06" izz="4.309323062170635e-06" ixy="0" ixz="0" iyz="0"/>
    </inertial>
    <visual name="left_hip_roll_link_visual">
      <origin xyz="0.0246449 -3.22e-06 -0.0172318" rpy="0.0 0.0 0.0"/>
      <geometry>
        <mesh filename="assets/left_hip_roll_link_visual.stl" scale="1.0 1.0 1.0"/>
      </geometry>
      <material name="hip_roll_link_visual_material"/>
    </visual>
  </link>
  <link name="left_hip_roll_body">
    <inertial>
      <origin xyz="0.0 0.0 0.0" rpy="0.0 0.0 0.0"/>
      <mass value="0.001"/>
      <inertia ixx="1e-09" iyy="1e-09" izz="1e-09" ixy="0" ixz="0" iyz="0"/>
    </inertial>
  </link>
  <joint type="revolute" name="left_hip_roll">
    <parent link="left_hip_pitch_link"/>
    <child link="left_hip_roll_body"/>
    <origin xyz="-0.023 0.019 -0.024" rpy="0.0 0.0 0.0"/>
    <axis xyz="1.0 0.0 0.0"/>
    <limit lower="-0.7853981633975363" upper="1.5707963267948084" effort="100" velocity="100"/>
  </joint>
  <joint type="fixed" name="left_hip_roll_offset">
    <parent link="left_hip_roll_body"/>
    <child link="left_hip_roll_link"/>
    <origin xyz="0.0 0.0 0.0" rpy="0.0 0.0 0.0"/>
  </joint>
  <link name="left_hip_yaw_link">
    <inertial>
      <origin xyz="-0.00967359 0.00117184 -0.0353305" rpy="-0.390642 -0.158031 0.0399734"/>
      <mass value="0.159688"/>
      <inertia ixx="7.953188969856982e-05" iyy="6.276982902063058e-05" izz="5.03525812807997e-05" ixy="0" ixz="0" iyz="0"/>
    </inertial>
    <visual name="left_hip_yaw_link_visual">
      <origin xyz="-0.00967359 0.00117184 -0.0353305" rpy="0.0 0.0 0.0"/>
      <geometry>
        <mesh filename="assets/left_hip_yaw_link_visual.stl" scale="1.0 1.0 1.0"/>
      </geometry>
      <material name="hip_yaw_link_visual_material"/>
    </visual>
    <collision name="left_hip_yaw_link_collision">
      <origin xyz="-0.009525 0.000575 -0.031475" rpy="0.0 0.0 0.0"/>
      <geometry>
        <box type="box" size="0.05905 0.04795 0.06295"/>
      </geometry>
    </collision>
  </link>
  <link name="left_hip_yaw_driven_body">
    <inertial>
      <origin xyz="0.0 0.0 0.0" rpy="0.0 0.0 0.0"/>
      <mass value="0.001"/>
      <inertia ixx="1e-09" iyy="1e-09" izz="1e-09" ixy="0" ixz="0" iyz="0"/>
    </inertial>
  </link>
  <joint type="revolute" name="left_hip_yaw_driven">
    <parent link="left_hip_roll_link"/>
    <child link="left_hip_yaw_driven_body"/>
    <origin xyz="0.023 0.0 -0.033" rpy="0.0 0.0 0.0"/>
    <axis xyz="0.0 0.0 -1.0"/>
    <limit lower="-1.570796326794896" upper="1.5707963267948972" effort="100" velocity="100"/>
  </joint>
  <joint type="fixed" name="left_hip_yaw_driven_offset">
    <parent link="left_hip_yaw_driven_body"/>
    <child link="left_hip_yaw_link"/>
    <origin xyz="0.0 0.0 0.0" rpy="0.0 0.0 0.0"/>
  </joint>
  <link name="left_hip_yaw_gear_drive">
    <inertial>
      <origin xyz="0.0 0.0 0.00175" rpy="1.5708 -1.5708 0.0"/>
      <mass value="0.001"/>
      <inertia ixx="4.7219e-08" iyy="2.46213e-08" izz="2.46213e-08" ixy="0" ixz="0" iyz="0"/>
    </inertial>
    <visual name="left_hip_yaw_gear_drive_visual">
      <origin xyz="0.0 0.0 0.00175" rpy="0.0 0.0 0.0"/>
      <geometry>
        <mesh filename="assets/left_hip_yaw_gear_drive_visual.stl" scale="1.0 1.0 1.0"/>
      </geometry>
      <material name="hip_yaw_gear_drive_visual_material"/>
    </visual>
  </link>
  <link name="left_hip_yaw_drive_body">
    <inertial>
      <origin xyz="0.0 0.0 0.0" rpy="0.0 0.0 0.0"/>
      <mass value="0.001"/>
      <inertia ixx="1e-09" iyy="1e-09" izz="1e-09" ixy="0" ixz="0" iyz="0"/>
    </inertial>
  </link>
  <joint type="fixed" name="left_hip_yaw_drive">
    <parent link="left_hip_yaw_link"/>
    <child link="left_hip_yaw_drive_body"/>
    <origin xyz="-0.0192 -0.0002 0.0" rpy="0.0 0.0 0.0"/>
  </joint>
  <joint type="fixed" name="left_hip_yaw_drive_offset">
    <parent link="left_hip_yaw_drive_body"/>
    <child link="left_hip_yaw_gear_drive"/>
    <origin xyz="0.0 0.0 0.0" rpy="0.0 0.0 0.0"/>
  </joint>
  <link name="left_knee_link">
    <inertial>
      <origin xyz="0.00452332 0.019 -0.0505695" rpy="1.5708 0.0 -0.00161648"/>
      <mass value="0.029"/>
      <inertia ixx="5.21356023262194e-05" iyy="4.23701e-05" izz="1.2975397673780586e-05" ixy="0" ixz="0" iyz="0"/>
    </inertial>
    <visual name="left_knee_link_visual">
      <origin xyz="0.00452332 0.019 -0.0505695" rpy="0.0 0.0 0.0"/>
      <geometry>
        <mesh filename="assets/left_knee_link_visual.stl" scale="1.0 1.0 1.0"/>
      </geometry>
      <material name="knee_link_visual_material"/>
    </visual>
    <collision name="left_knee_link_collision">
      <origin xyz="0.0 0.019 -0.0511526" rpy="0.0 0.0 0.0"/>
      <geometry>
        <box type="box" size="0.03 0.046 0.132305"/>
      </geometry>
    </collision>
  </link>
  <link name="left_knee_body">
    <inertial>
      <origin xyz="0.0 0.0 0.0" rpy="0.0 0.0 0.0"/>
      <mass value="0.001"/>
      <inertia ixx="1e-09" iyy="1e-09" izz="1e-09" ixy="0" ixz="0" iyz="0"/>
    </inertial>
  </link>
  <joint type="revolute" name="left_knee">
    <parent link="left_hip_yaw_link"/>
    <child link="left_knee_body"/>
    <origin xyz="0.0 -0.019 -0.0445" rpy="0.0 0.0 0.0"/>
    <axis xyz="0.0 -1.0 0.0"/>
    <limit lower="-2.0943951023931953" upper="0.0" effort="100" velocity="100"/>
  </joint>
  <joint type="fixed" name="left_knee_offset">
    <parent link="left_knee_body"/>
    <child link="left_knee_link"/>
    <origin xyz="0.0 0.0 0.0" rpy="0.0 0.0 0.0"/>
  </joint>
  <link name="left_ankle_pitch_link">
    <inertial>
      <origin xyz="-0.0179692 0.0188074 0.0120892" rpy="-0.309911 -1.56268 -2.80891"/>
      <mass value="0.172721"/>
      <inertia ixx="0.00012042651182353205" iyy="0.00010548652629092307" izz="4.63541618855447e-05" ixy="0" ixz="0" iyz="0"/>
    </inertial>
    <visual name="left_ankle_pitch_link_visual">
      <origin xyz="-0.0179692 0.0188074 0.0120892" rpy="0.0 0.0 0.0"/>
      <geometry>
        <mesh filename="assets/left_ankle_pitch_link_visual.stl" scale="1.0 1.0 1.0"/>
      </geometry>
      <material name="ankle_pitch_link_visual_material"/>
    </visual>
    <collision name="left_ankle_pitch_link_collision">
      <origin xyz="-0.01855 0.0168 0.012" rpy="0.0 0.0 0.0"/>
      <geometry>
        <box type="box" size="0.0869 0.0424 0.0465"/>
      </geometry>
    </collision>
  </link>
  <link name="left_ankle_pitch_body">
    <inertial>
      <origin xyz="0.0 0.0 0.0" rpy="0.0 0.0 0.0"/>
      <mass value="0.001"/>
      <inertia ixx="1e-09" iyy="1e-09" izz="1e-09" ixy="0" ixz="0" iyz="0"/>
    </inertial>
  </link>
  <joint type="revolute" name="left_ankle_pitch">
    <parent link="left_knee_link"/>
    <child link="left_ankle_pitch_body"/>
    <origin xyz="0.0 0.0 -0.11" rpy="0.0 0.0 0.0"/>
    <axis xyz="0.0 1.0 0.0"/>
    <limit lower="-1.8325957145940461" upper="0.9599310885968813" effort="100" velocity="100"/>
  </joint>
  <joint type="fixed" name="left_ankle_pitch_offset">
    <parent link="left_ankle_pitch_body"/>
    <child link="left_ankle_pitch_link"/>
    <origin xyz="0.0 0.0 0.0" rpy="0.0 0.0 0.0"/>
  </joint>
  <link name="left_ankle_roll_link">
    <inertial>
      <origin xyz="0.0358432 -7e-08 -0.0267229" rpy="-0.104864 -1.8642e-05 1.57073"/>
      <mass value="0.039"/>
      <inertia ixx="3.0430700009149677e-05" iyy="2.9026636819382057e-05" izz="8.651143171468227e-06" ixy="0" ixz="0" iyz="0"/>
    </inertial>
    <visual name="left_ankle_roll_link_visual">
      <origin xyz="0.0358432 -7e-08 -0.0267229" rpy="0.0 0.0 0.0"/>
      <geometry>
        <mesh filename="assets/left_ankle_roll_link_visual.stl" scale="1.0 1.0 1.0"/>
      </geometry>
      <material name="ankle_roll_link_visual_material"/>
    </visual>
    <collision name="left_ankle_roll_link_collision">
      <origin xyz="0.0358432 -7e-08 -0.0267229" rpy="0.0 0.0 0.0"/>
      <geometry>
        <mesh filename="assets/left_ankle_roll_link_collision.stl" scale="1.0 1.0 1.0"/>
      </geometry>
    </collision>
  </link>
  <link name="left_ankle_roll_body">
    <inertial>
      <origin xyz="0.0 0.0 0.0" rpy="0.0 0.0 0.0"/>
      <mass value="0.001"/>
      <inertia ixx="1e-09" iyy="1e-09" izz="1e-09" ixy="0" ixz="0" iyz="0"/>
    </inertial>
  </link>
  <joint type="revolute" name="left_ankle_roll">
    <parent link="left_ankle_pitch_link"/>
    <child link="left_ankle_roll_body"/>
    <origin xyz="-0.023 0.019 0.0" rpy="0.0 0.0 0.0"/>
    <axis xyz="1.0 0.0 0.0"/>
    <limit lower="-1.221730476395942" upper="1.2217304763961192" effort="100" velocity="100"/>
  </joint>
  <joint type="fixed" name="left_ankle_roll_offset">
    <parent link="left_ankle_roll_body"/>
    <child link="left_ankle_roll_link"/>
    <origin xyz="0.0 0.0 0.0" rpy="0.0 0.0 0.0"/>
  </joint>
  <link name="right_hip_pitch_link">
    <inertial>
      <origin xyz="-0.0202238 -0.0188253 -0.0117862" rpy="1.57611 0.00223173 1.57906"/>
      <mass value="0.188221"/>
      <inertia ixx="0.00013079657189784364" iyy="0.00011376770875309217" izz="5.023341934906426e-05" ixy="0" ixz="0" iyz="0"/>
    </inertial>
    <visual name="right_hip_pitch_link_visual">
      <origin xyz="-0.0202238 -0.0188253 -0.0117862" rpy="0.0 0.0 0.0"/>
      <geometry>
        <mesh filename="assets/right_hip_pitch_link_visual.stl" scale="1.0 1.0 1.0"/>
      </geometry>
      <material name="hip_pitch_link_visual_material"/>
    </visual>
    <collision name="right_hip_pitch_link_collision">
      <origin xyz="-0.0179687 -0.0168 -0.012" rpy="0.0 0.0 0.0"/>
      <geometry>
        <box type="box" size="0.0857375 0.0424 0.0465"/>
      </geometry>
    </collision>
  </link>
  <link name="right_hip_pitch_body">
    <inertial>
      <origin xyz="0.0 0.0 0.0" rpy="0.0 0.0 0.0"/>
      <mass value="0.001"/>
      <inertia ixx="1e-09" iyy="1e-09" izz="1e-09" ixy="0" ixz="0" iyz="0"/>
    </inertial>
  </link>
  <joint type="revolute" name="right_hip_pitch">
    <parent link="pelvis_link"/>
    <child link="right_hip_pitch_body"/>
    <origin xyz="-0.02275 -0.018 -0.0481" rpy="0.0 0.0 0.0"/>
    <axis xyz="0.0 -1.0 0.0"/>
    <limit lower="-0.7853981633974207" upper="2.3561944901923724" effort="100" velocity="100"/>
  </joint>
  <joint type="fixed" name="right_hip_pitch_offset">
    <parent link="right_hip_pitch_body"/>
    <child link="right_hip_pitch_link"/>
    <origin xyz="0.0 0.0 0.0" rpy="0.0 0.0 0.0"/>
  </joint>
  <link name="right_hip_roll_link">
    <inertial>
      <origin xyz="0.0246449 -3.22e-06 -0.0172318" rpy="0.0190768 -0.000313585 0.000387817"/>
      <mass value="0.022"/>
      <inertia ixx="9.951740710603494e-06" iyy="8.778876227225876e-06" izz="4.309323062170635e-06" ixy="0" ixz="0" iyz="0"/>
    </inertial>
    <visual name="right_hip_roll_link_visual">
      <origin xyz="0.0246449 -3.22e-06 -0.0172318" rpy="0.0 0.0 0.0"/>
      <geometry>
        <mesh filename="assets/right_hip_roll_link_visual.stl" scale="1.0 1.0 1.0"/>
      </geometry>
      <material name="hip_roll_link_visual_material"/>
    </visual>
  </link>
  <link name="right_hip_roll_body">
    <inertial>
      <origin xyz="0.0 0.0 0.0" rpy="0.0 0.0 0.0"/>
      <mass value="0.001"/>
      <inertia ixx="1e-09" iyy="1e-09" izz="1e-09" ixy="0" ixz="0" iyz="0"/>
    </inertial>
  </link>
  <joint type="revolute" name="right_hip_roll">
    <parent link="right_hip_pitch_link"/>
    <child link="right_hip_roll_body"/>
    <origin xyz="-0.0228375 -0.019 -0.024" rpy="0.0 0.0 0.0"/>
    <axis xyz="1.0 0.0 0.0"/>
    <limit lower="-1.5707963267948664" upper="0.7853981633974785" effort="100" velocity="100"/>
  </joint>
  <joint type="fixed" name="right_hip_roll_offset">
    <parent link="right_hip_roll_body"/>
    <child link="right_hip_roll_link"/>
    <origin xyz="0.0 0.0 0.0" rpy="0.0 0.0 0.0"/>
  </joint>
  <link name="right_hip_yaw_link">
    <inertial>
      <origin xyz="-0.00967257 -0.00117152 -0.0353303" rpy="-0.390028 0.158048 -0.0399683"/>
      <mass value="0.159688"/>
      <inertia ixx="7.952647039873605e-05" iyy="6.276452677935328e-05" izz="5.035170282191076e-05" ixy="0" ixz="0" iyz="0"/>
    </inertial>
    <visual name="right_hip_yaw_link_visual">
      <origin xyz="-0.00967257 -0.00117152 -0.0353303" rpy="0.0 0.0 0.0"/>
      <geometry>
        <mesh filename="assets/right_hip_yaw_link_visual.stl" scale="1.0 1.0 1.0"/>
      </geometry>
      <material name="hip_yaw_link_visual_material"/>
    </visual>
    <collision name="right_hip_yaw_link_collision">
      <origin xyz="-0.009525 -0.000575 -0.031475" rpy="0.0 0.0 0.0"/>
      <geometry>
        <box type="box" size="0.05905 0.04795 0.06295"/>
      </geometry>
    </collision>
  </link>
  <link name="right_hip_yaw_driven_body">
    <inertial>
      <origin xyz="0.0 0.0 0.0" rpy="0.0 0.0 0.0"/>
      <mass value="0.001"/>
      <inertia ixx="1e-09" iyy="1e-09" izz="1e-09" ixy="0" ixz="0" iyz="0"/>
    </inertial>
  </link>
  <joint type="revolute" name="right_hip_yaw_driven">
    <parent link="right_hip_roll_link"/>
    <child link="right_hip_yaw_driven_body"/>
    <origin xyz="0.023 0.0 -0.033" rpy="0.0 0.0 0.0"/>
    <axis xyz="0.0 0.0 -1.0"/>
    <limit lower="-1.570796326794897" upper="1.5707963267948961" effort="100" velocity="100"/>
  </joint>
  <joint type="fixed" name="right_hip_yaw_driven_offset">
    <parent link="right_hip_yaw_driven_body"/>
    <child link="right_hip_yaw_link"/>
    <origin xyz="0.0 0.0 0.0" rpy="0.0 0.0 0.0"/>
  </joint>
  <link name="right_hip_yaw_gear_drive">
    <inertial>
      <origin xyz="0.0 0.0 0.00175" rpy="1.5708 -1.5708 0.0"/>
      <mass value="0.001"/>
      <inertia ixx="4.7219e-08" iyy="2.46213e-08" izz="2.46213e-08" ixy="0" ixz="0" iyz="0"/>
    </inertial>
    <visual name="right_hip_yaw_gear_drive_visual">
      <origin xyz="0.0 0.0 0.00175" rpy="0.0 0.0 0.0"/>
      <geometry>
        <mesh filename="assets/right_hip_yaw_gear_drive_visual.stl" scale="1.0 1.0 1.0"/>
      </geometry>
      <material name="hip_yaw_gear_drive_visual_material"/>
    </visual>
  </link>
  <link name="right_hip_yaw_drive_body">
    <inertial>
      <origin xyz="0.0 0.0 0.0" rpy="0.0 0.0 0.0"/>
      <mass value="0.001"/>
      <inertia ixx="1e-09" iyy="1e-09" izz="1e-09" ixy="0" ixz="0" iyz="0"/>
    </inertial>
  </link>
  <joint type="fixed" name="right_hip_yaw_drive">
    <parent link="right_hip_yaw_link"/>
    <child link="right_hip_yaw_drive_body"/>
    <origin xyz="-0.0192 0.0002 0.0" rpy="0.0 0.0 0.0"/>
  </joint>
  <joint type="fixed" name="right_hip_yaw_drive_offset">
    <parent link="right_hip_yaw_drive_body"/>
    <child link="right_hip_yaw_gear_drive"/>
    <origin xyz="0.0 0.0 0.0" rpy="0.0 0.0 0.0"/>
  </joint>
  <link name="right_knee_link">
    <inertial>
      <origin xyz="0.00452332 -0.019 -0.0505695" rpy="1.5708 0.0 0.00161648"/>
      <mass value="0.029"/>
      <inertia ixx="5.21356023262194e-05" iyy="4.23701e-05" izz="1.2975397673780586e-05" ixy="0" ixz="0" iyz="0"/>
    </inertial>
    <visual name="right_knee_link_visual">
      <origin xyz="0.00452332 -0.019 -0.0505695" rpy="0.0 0.0 0.0"/>
      <geometry>
        <mesh filename="assets/right_knee_link_visual.stl" scale="1.0 1.0 1.0"/>
      </geometry>
      <material name="knee_link_visual_material"/>
    </visual>
    <collision name="right_knee_link_collision">
      <origin xyz="0.0 -0.019 -0.0511526" rpy="0.0 0.0 0.0"/>
      <geometry>
        <box type="box" size="0.03 0.046 0.132305"/>
      </geometry>
    </collision>
  </link>
  <link name="right_knee_body">
    <inertial>
      <origin xyz="0.0 0.0 0.0" rpy="0.0 0.0 0.0"/>
      <mass value="0.001"/>
      <inertia ixx="1e-09" iyy="1e-09" izz="1e-09" ixy="0" ixz="0" iyz="0"/>
    </inertial>
  </link>
  <joint type="revolute" name="right_knee">
    <parent link="right_hip_yaw_link"/>
    <child link="right_knee_body"/>
    <origin xyz="0.0 0.019 -0.0445" rpy="0.0 0.0 0.0"/>
    <axis xyz="0.0 1.0 0.0"/>
    <limit lower="0.0" upper="2.0943951023931953" effort="100" velocity="100"/>
  </joint>
  <joint type="fixed" name="right_knee_offset">
    <parent link="right_knee_body"/>
    <child link="right_knee_link"/>
    <origin xyz="0.0 0.0 0.0" rpy="0.0 0.0 0.0"/>
  </joint>
  <link name="right_ankle_pitch_link">
    <inertial>
      <origin xyz="-0.0179692 -0.018812 0.0120892" rpy="-2.92992 -1.56236 -0.234444"/>
      <mass value="0.172721"/>
      <inertia ixx="0.00012042708718664349" iyy="0.00010548657093012274" izz="4.635384188323382e-05" ixy="0" ixz="0" iyz="0"/>
    </inertial>
    <visual name="right_ankle_pitch_link_visual">
      <origin xyz="-0.0179692 -0.018812 0.0120892" rpy="0.0 0.0 0.0"/>
      <geometry>
        <mesh filename="assets/right_ankle_pitch_link_visual.stl" scale="1.0 1.0 1.0"/>
      </geometry>
      <material name="ankle_pitch_link_visual_material"/>
    </visual>
    <collision name="right_ankle_pitch_link_collision">
      <origin xyz="-0.01855 -0.0168 0.012" rpy="0.0 0.0 0.0"/>
      <geometry>
        <box type="box" size="0.0869 0.0424 0.0465"/>
      </geometry>
    </collision>
  </link>
  <link name="right_ankle_pitch_body">
    <inertial>
      <origin xyz="0.0 0.0 0.0" rpy="0.0 0.0 0.0"/>
      <mass value="0.001"/>
      <inertia ixx="1e-09" iyy="1e-09" izz="1e-09" ixy="0" ixz="0" iyz="0"/>
    </inertial>
  </link>
  <joint type="revolute" name="right_ankle_pitch">
    <parent link="right_knee_link"/>
    <child link="right_ankle_pitch_body"/>
    <origin xyz="0.0 0.0 -0.11" rpy="0.0 0.0 0.0"/>
    <axis xyz="0.0 -1.0 0.0"/>
    <limit lower="-0.9599310885968813" upper="1.8325957145940461" effort="100" velocity="100"/>
  </joint>
  <joint type="fixed" name="right_ankle_pitch_offset">
    <parent link="right_ankle_pitch_body"/>
    <child link="right_ankle_pitch_link"/>
    <origin xyz="0.0 0.0 0.0" rpy="0.0 0.0 0.0"/>
  </joint>
  <link name="right_ankle_roll_link">
    <inertial>
      <origin xyz="0.0358432 -7e-08 -0.0267229" rpy="-0.104864 -1.8642e-05 1.57073"/>
      <mass value="0.039"/>
      <inertia ixx="3.0430700009149677e-05" iyy="2.9026636819382057e-05" izz="8.651143171468227e-06" ixy="0" ixz="0" iyz="0"/>
    </inertial>
    <visual name="right_ankle_roll_link_visual">
      <origin xyz="0.0358432 -7e-08 -0.0267229" rpy="0.0 0.0 0.0"/>
      <geometry>
        <mesh filename="assets/right_ankle_roll_link_visual.stl" scale="1.0 1.0 1.0"/>
      </geometry>
      <material name="ankle_roll_link_visual_material"/>
    </visual>
    <collision name="right_ankle_roll_link_collision">
      <origin xyz="0.0358432 -7e-08 -0.0267229" rpy="0.0 0.0 0.0"/>
      <geometry>
        <mesh filename="assets/right_ankle_roll_link_collision.stl" scale="1.0 1.0 1.0"/>
      </geometry>
    </collision>
  </link>
  <link name="right_ankle_roll_body">
    <inertial>
      <origin xyz="0.0 0.0 0.0" rpy="0.0 0.0 0.0"/>
      <mass value="0.001"/>
      <inertia ixx="1e-09" iyy="1e-09" izz="1e-09" ixy="0" ixz="0" iyz="0"/>
    </inertial>
  </link>
  <joint type="revolute" name="right_ankle_roll">
    <parent link="right_ankle_pitch_link"/>
    <child link="right_ankle_roll_body"/>
    <origin xyz="-0.023 -0.019 0.0" rpy="0.0 0.0 0.0"/>
    <axis xyz="1.0 0.0 0.0"/>
    <limit lower="-1.221730476396059" upper="1.2217304763960022" effort="100" velocity="100"/>
  </joint>
  <joint type="fixed" name="right_ankle_roll_offset">
    <parent link="right_ankle_roll_body"/>
    <child link="right_ankle_roll_link"/>
    <origin xyz="0.0 0.0 0.0" rpy="0.0 0.0 0.0"/>
  </joint>
  <link name="left_shoulder_pitch_link">
    <inertial>
      <origin xyz="0.0 0.0129132 0.0" rpy="3.14159 -1.5708 0.0"/>
      <mass value="0.015"/>
      <inertia ixx="6.99606e-06" iyy="6.13264e-06" izz="3.20331e-06" ixy="0" ixz="0" iyz="0"/>
    </inertial>
    <visual name="left_shoulder_pitch_link_visual">
      <origin xyz="0.0 0.0129132 0.0" rpy="0.0 0.0 0.0"/>
      <geometry>
        <mesh filename="assets/left_shoulder_pitch_link_visual.stl" scale="1.0 1.0 1.0"/>
      </geometry>
      <material name="shoulder_pitch_link_visual_material"/>
    </visual>
  </link>
  <link name="left_shoulder_pitch_body">
    <inertial>
      <origin xyz="0.0 0.0 0.0" rpy="0.0 0.0 0.0"/>
      <mass value="0.001"/>
      <inertia ixx="1e-09" iyy="1e-09" izz="1e-09" ixy="0" ixz="0" iyz="0"/>
    </inertial>
  </link>
  <joint type="revolute" name="left_shoulder_pitch">
    <parent link="torso"/>
    <child link="left_shoulder_pitch_body"/>
    <origin xyz="-0.0200079 0.067 0.10175" rpy="0.0 0.0 0.0"/>
    <axis xyz="0.0 1.0 0.0"/>
    <limit lower="-4.712388980384688" upper="4.7123889803846915" effort="100" velocity="100"/>
  </joint>
  <joint type="fixed" name="left_shoulder_pitch_offset">
    <parent link="left_shoulder_pitch_body"/>
    <child link="left_shoulder_pitch_link"/>
    <origin xyz="0.0 0.0 0.0" rpy="0.0 0.0 0.0"/>
  </joint>
  <link name="left_shoulder_roll_link">
    <inertial>
      <origin xyz="0.0185402 0.0117736 -0.00203648" rpy="-1.55721 -1.33056 -1.491"/>
      <mass value="0.1152"/>
      <inertia ixx="3.485900290216656e-05" iyy="3.210267524717292e-05" izz="2.655632185066051e-05" ixy="0" ixz="0" iyz="0"/>
    </inertial>
    <visual name="left_shoulder_roll_link_visual">
      <origin xyz="0.0185402 0.0117736 -0.00203648" rpy="0.0 0.0 0.0"/>
      <geometry>
        <mesh filename="assets/left_shoulder_roll_link_visual.stl" scale="1.0 1.0 1.0"/>
      </geometry>
      <material name="shoulder_roll_link_visual_material"/>
    </visual>
    <collision name="left_shoulder_roll_link_collision">
      <origin xyz="0.01855 0.012 -0.003" rpy="0.0 0.0 0.0"/>
      <geometry>
        <box type="box" size="0.0409 0.0465 0.046"/>
      </geometry>
    </collision>
  </link>
  <link name="left_shoulder_roll_body">
    <inertial>
      <origin xyz="0.0 0.0 0.0" rpy="0.0 0.0 0.0"/>
      <mass value="0.001"/>
      <inertia ixx="1e-09" iyy="1e-09" izz="1e-09" ixy="0" ixz="0" iyz="0"/>
    </inertial>
  </link>
  <joint type="revolute" name="left_shoulder_roll">
    <parent link="left_shoulder_pitch_link"/>
    <child link="left_shoulder_roll_body"/>
    <origin xyz="-0.019 0.027 0.0" rpy="0.0 0.0 0.0"/>
    <axis xyz="1.0 0.0 0.0"/>
    <limit lower="-0.43633231299813" upper="1.5707963267953489" effort="100" velocity="100"/>
  </joint>
  <joint type="fixed" name="left_shoulder_roll_offset">
    <parent link="left_shoulder_roll_body"/>
    <child link="left_shoulder_roll_link"/>
    <origin xyz="0.0 0.0 0.0" rpy="0.0 0.0 0.0"/>
  </joint>
  <link name="left_shoulder_gear_drive">
    <inertial>
      <origin xyz="0.0 0.0 -0.00662386" rpy="1.5708 -1.5708 0.0"/>
      <mass value="0.004"/>
      <inertia ixx="2.87762e-07" iyy="1.9527e-07" izz="1.9527e-07" ixy="0" ixz="0" iyz="0"/>
    </inertial>
    <visual name="left_shoulder_gear_drive_visual">
      <origin xyz="0.0 0.0 -0.00662386" rpy="0.0 0.0 0.0"/>
      <geometry>
        <mesh filename="assets/left_shoulder_gear_drive_visual.stl" scale="1.0 1.0 1.0"/>
      </geometry>
      <material name="shoulder_gear_drive_visual_material"/>
    </visual>
  </link>
  <link name="left_shoulder_yaw_drive_body">
    <inertial>
      <origin xyz="0.0 0.0 0.0" rpy="0.0 0.0 0.0"/>
      <mass value="0.001"/>
      <inertia ixx="1e-09" iyy="1e-09" izz="1e-09" ixy="0" ixz="0" iyz="0"/>
    </inertial>
  </link>
  <joint type="fixed" name="left_shoulder_yaw_drive">
    <parent link="left_shoulder_roll_link"/>
    <child link="left_shoulder_yaw_drive_body"/>
    <origin xyz="0.019 0.024 -0.019" rpy="0.0 0.0 0.0"/>
  </joint>
  <joint type="fixed" name="left_shoulder_yaw_drive_offset">
    <parent link="left_shoulder_yaw_drive_body"/>
    <child link="left_shoulder_gear_drive"/>
    <origin xyz="0.0 0.0 0.0" rpy="0.0 0.0 0.0"/>
  </joint>
  <link name="left_shoulder_yaw_link">
    <inertial>
      <origin xyz="-2.1e-07 2.4e-07 -0.0257842" rpy="3.15025e-05 1.32686e-05 1.57079"/>
      <mass value="0.0247439"/>
      <inertia ixx="1.5406300001554995e-05" iyy="1.0150900003068194e-05" izz="6.98607999537679e-06" ixy="0" ixz="0" iyz="0"/>
    </inertial>
    <visual name="left_shoulder_yaw_link_visual">
      <origin xyz="-2.1e-07 2.4e-07 -0.0257842" rpy="0.0 0.0 0.0"/>
      <geometry>
        <mesh filename="assets/left_shoulder_yaw_link_visual.stl" scale="1.0 1.0 1.0"/>
      </geometry>
      <material name="shoulder_yaw_link_visual_material"/>
    </visual>
    <collision name="left_shoulder_yaw_link_collision">
      <origin xyz="0.0 0.0 -0.04425" rpy="0.0 0.0 0.0"/>
      <geometry>
        <box type="box" size="0.046 0.025985 0.054214"/>
      </geometry>
    </collision>
  </link>
  <link name="left_shoulder_yaw_driven_body">
    <inertial>
      <origin xyz="0.0 0.0 0.0" rpy="0.0 0.0 0.0"/>
      <mass value="0.001"/>
      <inertia ixx="1e-09" iyy="1e-09" izz="1e-09" ixy="0" ixz="0" iyz="0"/>
    </inertial>
  </link>
  <joint type="revolute" name="left_shoulder_yaw_driven">
    <parent link="left_shoulder_roll_link"/>
    <child link="left_shoulder_yaw_driven_body"/>
    <origin xyz="0.019 0.0 -0.025" rpy="0.0 0.0 0.0"/>
    <axis xyz="0.0 0.0 -1.0"/>
    <limit lower="-3.141592653589787" upper="3.1415926535897993" effort="100" velocity="100"/>
  </joint>
  <joint type="fixed" name="left_shoulder_yaw_driven_offset">
    <parent link="left_shoulder_yaw_driven_body"/>
    <child link="left_shoulder_yaw_link"/>
    <origin xyz="0.0 0.0 0.0" rpy="0.0 0.0 0.0"/>
  </joint>
  <link name="left_elbow_roll_link">
    <inertial>
      <origin xyz="0.0185402 0.0117736 -0.00203648" rpy="1.58439 -1.33056 1.65059"/>
      <mass value="0.1152"/>
      <inertia ixx="3.485900290216656e-05" iyy="3.210267524717292e-05" izz="2.655632185066051e-05" ixy="0" ixz="0" iyz="0"/>
    </inertial>
    <visual name="left_elbow_roll_link_visual">
      <origin xyz="0.0185402 0.0117736 -0.00203648" rpy="0.0 0.0 0.0"/>
      <geometry>
        <mesh filename="assets/left_elbow_roll_link_visual.stl" scale="1.0 1.0 1.0"/>
      </geometry>
      <material name="elbow_roll_link_visual_material"/>
    </visual>
    <collision name="left_elbow_roll_link_collision">
      <origin xyz="0.01855 0.012 -0.003" rpy="0.0 0.0 0.0"/>
      <geometry>
        <box type="box" size="0.0409 0.0465 0.046"/>
      </geometry>
    </collision>
  </link>
  <link name="left_elbow_roll_body">
    <inertial>
      <origin xyz="0.0 0.0 0.0" rpy="0.0 0.0 0.0"/>
      <mass value="0.001"/>
      <inertia ixx="1e-09" iyy="1e-09" izz="1e-09" ixy="0" ixz="0" iyz="0"/>
    </inertial>
  </link>
  <joint type="revolute" name="left_elbow_roll">
    <parent link="left_shoulder_yaw_link"/>
    <child link="left_elbow_roll_body"/>
    <origin xyz="-0.019 0.0 -0.061" rpy="0.0 0.0 0.0"/>
    <axis xyz="1.0 0.0 0.0"/>
    <limit lower="-2.2689280275929393" upper="1.9198621771934516" effort="100" velocity="100"/>
  </joint>
  <joint type="fixed" name="left_elbow_roll_offset">
    <parent link="left_elbow_roll_body"/>
    <child link="left_elbow_roll_link"/>
    <origin xyz="0.0 0.0 0.0" rpy="0.0 0.0 0.0"/>
  </joint>
  <link name="left_elbow_gear_drive">
    <inertial>
      <origin xyz="0.0 0.0 -0.00662386" rpy="1.5708 -1.5708 0.0"/>
      <mass value="0.004"/>
      <inertia ixx="2.87762e-07" iyy="1.9527e-07" izz="1.9527e-07" ixy="0" ixz="0" iyz="0"/>
    </inertial>
    <visual name="left_elbow_gear_drive_visual">
      <origin xyz="0.0 0.0 -0.00662386" rpy="0.0 0.0 0.0"/>
      <geometry>
        <mesh filename="assets/left_elbow_gear_drive_visual.stl" scale="1.0 1.0 1.0"/>
      </geometry>
      <material name="elbow_gear_drive_visual_material"/>
    </visual>
  </link>
  <link name="left_elbow_yaw_drive_body">
    <inertial>
      <origin xyz="0.0 0.0 0.0" rpy="0.0 0.0 0.0"/>
      <mass value="0.001"/>
      <inertia ixx="1e-09" iyy="1e-09" izz="1e-09" ixy="0" ixz="0" iyz="0"/>
    </inertial>
  </link>
  <joint type="fixed" name="left_elbow_yaw_drive">
    <parent link="left_elbow_roll_link"/>
    <child link="left_elbow_yaw_drive_body"/>
    <origin xyz="0.019 0.024 -0.019" rpy="0.0 0.0 0.0"/>
  </joint>
  <joint type="fixed" name="left_elbow_yaw_drive_offset">
    <parent link="left_elbow_yaw_drive_body"/>
    <child link="left_elbow_gear_drive"/>
    <origin xyz="0.0 0.0 0.0" rpy="0.0 0.0 0.0"/>
  </joint>
  <link name="left_elbow_yaw_link">
    <inertial>
      <origin xyz="2.3e-07 0.00269789 -0.0333792" rpy="0.198464 2.71652e-05 2.88648e-05"/>
      <mass value="0.0302318"/>
      <inertia ixx="2.8986700022079142e-05" iyy="1.744118776305497e-05" izz="1.3670312214865846e-05" ixy="0" ixz="0" iyz="0"/>
    </inertial>
    <visual name="left_elbow_yaw_link_visual">
      <origin xyz="2.3e-07 0.00269789 -0.0333792" rpy="0.0 0.0 0.0"/>
      <geometry>
        <mesh filename="assets/left_elbow_yaw_link_visual.stl" scale="1.0 1.0 1.0"/>
      </geometry>
      <material name="elbow_yaw_link_visual_material"/>
    </visual>
    <collision name="left_elbow_yaw_link_collision">
      <origin xyz="0.0 0.00335 -0.04475" rpy="0.0 0.0 0.0"/>
      <geometry>
        <box type="box" size="0.025985 0.0593 0.055126"/>
      </geometry>
    </collision>
  </link>
  <link name="left_elbow_yaw_driven_body">
    <inertial>
      <origin xyz="0.0 0.0 0.0" rpy="0.0 0.0 0.0"/>
      <mass value="0.001"/>
      <inertia ixx="1e-09" iyy="1e-09" izz="1e-09" ixy="0" ixz="0" iyz="0"/>
    </inertial>
  </link>
  <joint type="revolute" name="left_elbow_yaw_driven">
    <parent link="left_elbow_roll_link"/>
    <child link="left_elbow_yaw_driven_body"/>
    <origin xyz="0.019 0.0 -0.025" rpy="0.0 0.0 0.0"/>
    <axis xyz="0.0 0.0 -1.0"/>
    <limit lower="-3.141592653589793" upper="3.141592653589793" effort="100" velocity="100"/>
  </joint>
  <joint type="fixed" name="left_elbow_yaw_driven_offset">
    <parent link="left_elbow_yaw_driven_body"/>
    <child link="left_elbow_yaw_link"/>
    <origin xyz="0.0 0.0 0.0" rpy="0.0 0.0 0.0"/>
  </joint>
  <link name="left_wrist_pitch_link">
    <inertial>
      <origin xyz="-0.00041505 -0.0218671 0.011496" rpy="1.49671 -0.0905321 1.57075"/>
      <mass value="0.1276"/>
      <inertia ixx="4.1637540552898234e-05" iyy="3.5701830149312975e-05" izz="3.2969929297788734e-05" ixy="0" ixz="0" iyz="0"/>
    </inertial>
    <visual name="left_wrist_pitch_link_visual">
      <origin xyz="-0.00041505 -0.0218671 0.011496" rpy="0.0 0.0 0.0"/>
      <geometry>
        <mesh filename="assets/left_wrist_pitch_link_visual.stl" scale="1.0 1.0 1.0"/>
      </geometry>
      <material name="wrist_pitch_link_visual_material"/>
    </visual>
    <collision name="left_wrist_pitch_link_collision">
      <origin xyz="-0.00045 -0.0215 0.012" rpy="0.0 0.0 0.0"/>
      <geometry>
        <box type="box" size="0.0409 0.045 0.0465"/>
      </geometry>
    </collision>
  </link>
  <link name="left_wrist_pitch_driven_body">
    <inertial>
      <origin xyz="0.0 0.0 0.0" rpy="0.0 0.0 0.0"/>
      <mass value="0.001"/>
      <inertia ixx="1e-09" iyy="1e-09" izz="1e-09" ixy="0" ixz="0" iyz="0"/>
    </inertial>
  </link>
  <joint type="revolute" name="left_wrist_pitch_driven">
    <parent link="left_elbow_yaw_link"/>
    <child link="left_wrist_pitch_driven_body"/>
    <origin xyz="0.0 0.022 -0.061" rpy="0.0 0.0 0.0"/>
    <axis xyz="0.0 -1.0 0.0"/>
    <limit lower="-2.094395102392591" upper="2.0943951023937997" effort="100" velocity="100"/>
  </joint>
  <joint type="fixed" name="left_wrist_pitch_driven_offset">
    <parent link="left_wrist_pitch_driven_body"/>
    <child link="left_wrist_pitch_link"/>
    <origin xyz="0.0 0.0 0.0" rpy="0.0 0.0 0.0"/>
  </joint>
  <link name="left_wrist_gear_drive">
    <inertial>
      <origin xyz="0.0 0.00503438 0.0" rpy="1.5708 -1.5708 0.0"/>
      <mass value="0.003"/>
      <inertia ixx="2.24433e-07" iyy="1.33264e-07" izz="1.33264e-07" ixy="0" ixz="0" iyz="0"/>
    </inertial>
    <visual name="left_wrist_gear_drive_visual">
      <origin xyz="0.0 0.00503438 0.0" rpy="0.0 0.0 0.0"/>
      <geometry>
        <mesh filename="assets/left_wrist_gear_drive_visual.stl" scale="1.0 1.0 1.0"/>
      </geometry>
      <material name="wrist_gear_drive_visual_material"/>
    </visual>
  </link>
  <link name="left_wrist_pitch_drive_body">
    <inertial>
      <origin xyz="0.0 0.0 0.0" rpy="0.0 0.0 0.0"/>
      <mass value="0.001"/>
      <inertia ixx="1e-09" iyy="1e-09" izz="1e-09" ixy="0" ixz="0" iyz="0"/>
    </inertial>
  </link>
  <joint type="fixed" name="left_wrist_pitch_drive">
    <parent link="left_wrist_pitch_link"/>
    <child link="left_wrist_pitch_drive_body"/>
    <origin xyz="0.0 -0.003 0.024" rpy="0.0 0.0 0.0"/>
  </joint>
  <joint type="fixed" name="left_wrist_pitch_drive_offset">
    <parent link="left_wrist_pitch_drive_body"/>
    <child link="left_wrist_gear_drive"/>
    <origin xyz="0.0 0.0 0.0" rpy="0.0 0.0 0.0"/>
  </joint>
  <link name="left_hand">
    <inertial>
      <origin xyz="0.0176215 0.00315051 -0.0386545" rpy="-0.0500507 -0.00462013 -0.292205"/>
      <mass value="0.043"/>
      <inertia ixx="3.0144687136750248e-05" iyy="2.6382668397182114e-05" izz="1.700364446606766e-05" ixy="0" ixz="0" iyz="0"/>
    </inertial>
    <visual name="left_hand_visual">
      <origin xyz="0.0176215 0.00315051 -0.0386545" rpy="0.0 0.0 0.0"/>
      <geometry>
        <mesh filename="assets/left_hand_visual.stl" scale="1.0 1.0 1.0"/>
      </geometry>
      <material name="hand_visual_material"/>
    </visual>
    <collision name="left_hand_collision">
      <origin xyz="0.0205398 0.0045 -0.047" rpy="0.0 0.0 0.0"/>
      <geometry>
        <box type="box" size="0.074 0.05 0.02"/>
      </geometry>
    </collision>
  </link>
  <link name="left_wrist_roll_body">
    <inertial>
      <origin xyz="0.0 0.0 0.0" rpy="0.0 0.0 0.0"/>
      <mass value="0.001"/>
      <inertia ixx="1e-09" iyy="1e-09" izz="1e-09" ixy="0" ixz="0" iyz="0"/>
    </inertial>
  </link>
  <joint type="revolute" name="left_wrist_roll">
    <parent link="left_wrist_pitch_link"/>
    <child link="left_wrist_roll_body"/>
    <origin xyz="-0.019 -0.022 0.0" rpy="0.0 0.0 0.0"/>
    <axis xyz="-1.0 0.0 0.0"/>
    <limit lower="-1.5707963267948966" upper="1.5707963267948966" effort="100" velocity="100"/>
  </joint>
  <joint type="fixed" name="left_wrist_roll_offset">
    <parent link="left_wrist_roll_body"/>
    <child link="left_hand"/>
    <origin xyz="0.0 0.0 0.0" rpy="0.0 0.0 0.0"/>
  </joint>
  <link name="right_shoulder_pitch_link">
    <inertial>
      <origin xyz="0.0 -0.0129132 0.0" rpy="3.14159 -1.5708 0.0"/>
      <mass value="0.015"/>
      <inertia ixx="6.99606e-06" iyy="6.13264e-06" izz="3.20331e-06" ixy="0" ixz="0" iyz="0"/>
    </inertial>
    <visual name="right_shoulder_pitch_link_visual">
      <origin xyz="0.0 -0.0129132 0.0" rpy="0.0 0.0 0.0"/>
      <geometry>
        <mesh filename="assets/right_shoulder_pitch_link_visual.stl" scale="1.0 1.0 1.0"/>
      </geometry>
      <material name="shoulder_pitch_link_visual_material"/>
    </visual>
  </link>
  <link name="right_shoulder_pitch_body">
    <inertial>
      <origin xyz="0.0 0.0 0.0" rpy="0.0 0.0 0.0"/>
      <mass value="0.001"/>
      <inertia ixx="1e-09" iyy="1e-09" izz="1e-09" ixy="0" ixz="0" iyz="0"/>
    </inertial>
  </link>
  <joint type="revolute" name="right_shoulder_pitch">
    <parent link="torso"/>
    <child link="right_shoulder_pitch_body"/>
    <origin xyz="-0.0200079 -0.067 0.10175" rpy="0.0 0.0 0.0"/>
    <axis xyz="0.0 -1.0 0.0"/>
    <limit lower="-4.71238898038469" upper="4.71238898038469" effort="100" velocity="100"/>
  </joint>
  <joint type="fixed" name="right_shoulder_pitch_offset">
    <parent link="right_shoulder_pitch_body"/>
    <child link="right_shoulder_pitch_link"/>
    <origin xyz="0.0 0.0 0.0" rpy="0.0 0.0 0.0"/>
  </joint>
  <link name="right_shoulder_roll_link">
    <inertial>
      <origin xyz="-0.0185402 -0.0117736 -0.00203648" rpy="-1.55721 -1.33056 -1.491"/>
      <mass value="0.1152"/>
      <inertia ixx="3.485900290216656e-05" iyy="3.210267524717292e-05" izz="2.655632185066051e-05" ixy="0" ixz="0" iyz="0"/>
    </inertial>
    <visual name="right_shoulder_roll_link_visual">
      <origin xyz="-0.0185402 -0.0117736 -0.00203648" rpy="0.0 0.0 0.0"/>
      <geometry>
        <mesh filename="assets/right_shoulder_roll_link_visual.stl" scale="1.0 1.0 1.0"/>
      </geometry>
      <material name="shoulder_roll_link_visual_material"/>
    </visual>
    <collision name="right_shoulder_roll_link_collision">
      <origin xyz="-0.01855 -0.012 -0.003" rpy="0.0 0.0 0.0"/>
      <geometry>
        <box type="box" size="0.0409 0.0465 0.046"/>
      </geometry>
    </collision>
  </link>
  <link name="right_shoulder_roll_body">
    <inertial>
      <origin xyz="0.0 0.0 0.0" rpy="0.0 0.0 0.0"/>
      <mass value="0.001"/>
      <inertia ixx="1e-09" iyy="1e-09" izz="1e-09" ixy="0" ixz="0" iyz="0"/>
    </inertial>
  </link>
  <joint type="revolute" name="right_shoulder_roll">
    <parent link="right_shoulder_pitch_link"/>
    <child link="right_shoulder_roll_body"/>
    <origin xyz="0.019 -0.027 0.0" rpy="0.0 0.0 0.0"/>
    <axis xyz="-1.0 0.0 0.0"/>
    <limit lower="-0.4363323129976375" upper="1.5707963267958416" effort="100" velocity="100"/>
  </joint>
  <joint type="fixed" name="right_shoulder_roll_offset">
    <parent link="right_shoulder_roll_body"/>
    <child link="right_shoulder_roll_link"/>
    <origin xyz="0.0 0.0 0.0" rpy="0.0 0.0 0.0"/>
  </joint>
  <link name="right_shoulder_gear_drive">
    <inertial>
      <origin xyz="0.0 0.0 -0.00662386" rpy="1.5708 -1.5708 0.0"/>
      <mass value="0.004"/>
      <inertia ixx="2.87762e-07" iyy="1.9527e-07" izz="1.9527e-07" ixy="0" ixz="0" iyz="0"/>
    </inertial>
    <visual name="right_shoulder_gear_drive_visual">
      <origin xyz="0.0 0.0 -0.00662386" rpy="0.0 0.0 0.0"/>
      <geometry>
        <mesh filename="assets/right_shoulder_gear_drive_visual.stl" scale="1.0 1.0 1.0"/>
      </geometry>
      <material name="shoulder_gear_drive_visual_material"/>
    </visual>
  </link>
  <link name="right_shoulder_yaw_drive_body">
    <inertial>
      <origin xyz="0.0 0.0 0.0" rpy="0.0 0.0 0.0"/>
      <mass value="0.001"/>
      <inertia ixx="1e-09" iyy="1e-09" izz="1e-09" ixy="0" ixz="0" iyz="0"/>
    </inertial>
  </link>
  <joint type="fixed" name="right_shoulder_yaw_drive">
    <parent link="right_shoulder_roll_link"/>
    <child link="right_shoulder_yaw_drive_body"/>
    <origin xyz="-0.019 -0.024 -0.019" rpy="0.0 0.0 0.0"/>
  </joint>
  <joint type="fixed" name="right_shoulder_yaw_drive_offset">
    <parent link="right_shoulder_yaw_drive_body"/>
    <child link="right_shoulder_gear_drive"/>
    <origin xyz="0.0 0.0 0.0" rpy="0.0 0.0 0.0"/>
  </joint>
  <link name="right_shoulder_yaw_link">
    <inertial>
      <origin xyz="2.1e-07 -2.4e-07 -0.0257842" rpy="3.15025e-05 1.32686e-05 1.57079"/>
      <mass value="0.0247439"/>
      <inertia ixx="1.5406300001554995e-05" iyy="1.0150900003068194e-05" izz="6.98607999537679e-06" ixy="0" ixz="0" iyz="0"/>
    </inertial>
    <visual name="right_shoulder_yaw_link_visual">
      <origin xyz="2.1e-07 -2.4e-07 -0.0257842" rpy="0.0 0.0 0.0"/>
      <geometry>
        <mesh filename="assets/right_shoulder_yaw_link_visual.stl" scale="1.0 1.0 1.0"/>
      </geometry>
      <material name="shoulder_yaw_link_visual_material"/>
    </visual>
    <collision name="right_shoulder_yaw_link_collision">
      <origin xyz="0.0 0.0 -0.04425" rpy="0.0 0.0 0.0"/>
      <geometry>
        <box type="box" size="0.046 0.025985 0.054214"/>
      </geometry>
    </collision>
  </link>
  <link name="right_shoulder_yaw_driven_body">
    <inertial>
      <origin xyz="0.0 0.0 0.0" rpy="0.0 0.0 0.0"/>
      <mass value="0.001"/>
      <inertia ixx="1e-09" iyy="1e-09" izz="1e-09" ixy="0" ixz="0" iyz="0"/>
    </inertial>
  </link>
  <joint type="revolute" name="right_shoulder_yaw_driven">
    <parent link="right_shoulder_roll_link"/>
    <child link="right_shoulder_yaw_driven_body"/>
    <origin xyz="-0.019 0.0 -0.025" rpy="0.0 0.0 0.0"/>
    <axis xyz="0.0 0.0 -1.0"/>
    <limit lower="-3.14159265358975" upper="3.141592653589836" effort="100" velocity="100"/>
  </joint>
  <joint type="fixed" name="right_shoulder_yaw_driven_offset">
    <parent link="right_shoulder_yaw_driven_body"/>
    <child link="right_shoulder_yaw_link"/>
    <origin xyz="0.0 0.0 0.0" rpy="0.0 0.0 0.0"/>
  </joint>
  <link name="right_elbow_roll_link">
    <inertial>
      <origin xyz="-0.0185402 -0.0117736 -0.00203648" rpy="1.58439 -1.33056 1.65059"/>
      <mass value="0.1152"/>
      <inertia ixx="3.485900290216656e-05" iyy="3.210267524717292e-05" izz="2.655632185066051e-05" ixy="0" ixz="0" iyz="0"/>
    </inertial>
    <visual name="right_elbow_roll_link_visual">
      <origin xyz="-0.0185402 -0.0117736 -0.00203648" rpy="0.0 0.0 0.0"/>
      <geometry>
        <mesh filename="assets/right_elbow_roll_link_visual.stl" scale="1.0 1.0 1.0"/>
      </geometry>
      <material name="elbow_roll_link_visual_material"/>
    </visual>
    <collision name="right_elbow_roll_link_collision">
      <origin xyz="-0.01855 -0.012 -0.003" rpy="0.0 0.0 0.0"/>
      <geometry>
        <box type="box" size="0.0409 0.0465 0.046"/>
      </geometry>
    </collision>
  </link>
  <link name="right_elbow_roll_body">
    <inertial>
      <origin xyz="0.0 0.0 0.0" rpy="0.0 0.0 0.0"/>
      <mass value="0.001"/>
      <inertia ixx="1e-09" iyy="1e-09" izz="1e-09" ixy="0" ixz="0" iyz="0"/>
    </inertial>
  </link>
  <joint type="revolute" name="right_elbow_roll">
    <parent link="right_shoulder_yaw_link"/>
    <child link="right_elbow_roll_body"/>
    <origin xyz="0.019 0.0 -0.061" rpy="0.0 0.0 0.0"/>
    <axis xyz="-1.0 0.0 0.0"/>
    <limit lower="-2.2689280275929393" upper="1.9198621771934514" effort="100" velocity="100"/>
  </joint>
  <joint type="fixed" name="right_elbow_roll_offset">
    <parent link="right_elbow_roll_body"/>
    <child link="right_elbow_roll_link"/>
    <origin xyz="0.0 0.0 0.0" rpy="0.0 0.0 0.0"/>
  </joint>
  <link name="right_elbow_gear_drive">
    <inertial>
      <origin xyz="0.0 0.0 -0.00662386" rpy="1.5708 -1.5708 0.0"/>
      <mass value="0.004"/>
      <inertia ixx="2.87762e-07" iyy="1.9527e-07" izz="1.9527e-07" ixy="0" ixz="0" iyz="0"/>
    </inertial>
    <visual name="right_elbow_gear_drive_visual">
      <origin xyz="0.0 0.0 -0.00662386" rpy="0.0 0.0 0.0"/>
      <geometry>
        <mesh filename="assets/right_elbow_gear_drive_visual.stl" scale="1.0 1.0 1.0"/>
      </geometry>
      <material name="elbow_gear_drive_visual_material"/>
    </visual>
  </link>
  <link name="right_elbow_yaw_drive_body">
    <inertial>
      <origin xyz="0.0 0.0 0.0" rpy="0.0 0.0 0.0"/>
      <mass value="0.001"/>
      <inertia ixx="1e-09" iyy="1e-09" izz="1e-09" ixy="0" ixz="0" iyz="0"/>
    </inertial>
  </link>
  <joint type="fixed" name="right_elbow_yaw_drive">
    <parent link="right_elbow_roll_link"/>
    <child link="right_elbow_yaw_drive_body"/>
    <origin xyz="-0.019 -0.024 -0.019" rpy="0.0 0.0 0.0"/>
  </joint>
  <joint type="fixed" name="right_elbow_yaw_drive_offset">
    <parent link="right_elbow_yaw_drive_body"/>
    <child link="right_elbow_gear_drive"/>
    <origin xyz="0.0 0.0 0.0" rpy="0.0 0.0 0.0"/>
  </joint>
  <link name="right_elbow_yaw_link">
    <inertial>
      <origin xyz="-2.3e-07 -0.00269789 -0.0333792" rpy="0.198464 2.71652e-05 2.88648e-05"/>
      <mass value="0.0302318"/>
      <inertia ixx="2.8986700022079142e-05" iyy="1.744118776305497e-05" izz="1.3670312214865846e-05" ixy="0" ixz="0" iyz="0"/>
    </inertial>
    <visual name="right_elbow_yaw_link_visual">
      <origin xyz="-2.3e-07 -0.00269789 -0.0333792" rpy="0.0 0.0 0.0"/>
      <geometry>
        <mesh filename="assets/right_elbow_yaw_link_visual.stl" scale="1.0 1.0 1.0"/>
      </geometry>
      <material name="elbow_yaw_link_visual_material"/>
    </visual>
    <collision name="right_elbow_yaw_link_collision">
      <origin xyz="0.0 -0.00335 -0.04475" rpy="0.0 0.0 0.0"/>
      <geometry>
        <box type="box" size="0.025985 0.0593 0.055126"/>
      </geometry>
    </collision>
  </link>
  <link name="right_elbow_yaw_driven_body">
    <inertial>
      <origin xyz="0.0 0.0 0.0" rpy="0.0 0.0 0.0"/>
      <mass value="0.001"/>
      <inertia ixx="1e-09" iyy="1e-09" izz="1e-09" ixy="0" ixz="0" iyz="0"/>
    </inertial>
  </link>
  <joint type="revolute" name="right_elbow_yaw_driven">
    <parent link="right_elbow_roll_link"/>
    <child link="right_elbow_yaw_driven_body"/>
    <origin xyz="-0.019 0.0 -0.025" rpy="0.0 0.0 0.0"/>
    <axis xyz="0.0 0.0 -1.0"/>
    <limit lower="-3.1415926535897016" upper="3.1415926535898846" effort="100" velocity="100"/>
  </joint>
  <joint type="fixed" name="right_elbow_yaw_driven_offset">
    <parent link="right_elbow_yaw_driven_body"/>
    <child link="right_elbow_yaw_link"/>
    <origin xyz="0.0 0.0 0.0" rpy="0.0 0.0 0.0"/>
  </joint>
  <link name="right_wrist_pitch_link">
    <inertial>
      <origin xyz="0.00041505 0.0218671 0.011496" rpy="1.49671 -0.0905321 1.57075"/>
      <mass value="0.1276"/>
      <inertia ixx="4.1637540552898234e-05" iyy="3.5701830149312975e-05" izz="3.2969929297788734e-05" ixy="0" ixz="0" iyz="0"/>
    </inertial>
    <visual name="right_wrist_pitch_link_visual">
      <origin xyz="0.00041505 0.0218671 0.011496" rpy="0.0 0.0 0.0"/>
      <geometry>
        <mesh filename="assets/right_wrist_pitch_link_visual.stl" scale="1.0 1.0 1.0"/>
      </geometry>
      <material name="wrist_pitch_link_visual_material"/>
    </visual>
    <collision name="right_wrist_pitch_link_collision">
      <origin xyz="0.00045 0.0215 0.012" rpy="0.0 0.0 0.0"/>
      <geometry>
        <box type="box" size="0.0409 0.045 0.0465"/>
      </geometry>
    </collision>
  </link>
  <link name="right_wrist_pitch_driven_body">
    <inertial>
      <origin xyz="0.0 0.0 0.0" rpy="0.0 0.0 0.0"/>
      <mass value="0.001"/>
      <inertia ixx="1e-09" iyy="1e-09" izz="1e-09" ixy="0" ixz="0" iyz="0"/>
    </inertial>
  </link>
  <joint type="revolute" name="right_wrist_pitch_driven">
    <parent link="right_elbow_yaw_link"/>
    <child link="right_wrist_pitch_driven_body"/>
    <origin xyz="0.0 -0.022 -0.061" rpy="0.0 0.0 0.0"/>
    <axis xyz="0.0 1.0 0.0"/>
    <limit lower="-2.0943951023930802" upper="2.0943951023933103" effort="100" velocity="100"/>
  </joint>
  <joint type="fixed" name="right_wrist_pitch_driven_offset">
    <parent link="right_wrist_pitch_driven_body"/>
    <child link="right_wrist_pitch_link"/>
    <origin xyz="0.0 0.0 0.0" rpy="0.0 0.0 0.0"/>
  </joint>
  <link name="right_wrist_gear_drive">
    <inertial>
      <origin xyz="0.0 -0.00503438 0.0" rpy="1.5708 -1.5708 0.0"/>
      <mass value="0.003"/>
      <inertia ixx="2.24433e-07" iyy="1.33264e-07" izz="1.33264e-07" ixy="0" ixz="0" iyz="0"/>
    </inertial>
    <visual name="right_wrist_gear_drive_visual">
      <origin xyz="0.0 -0.00503438 0.0" rpy="0.0 0.0 0.0"/>
      <geometry>
        <mesh filename="assets/right_wrist_gear_drive_visual.stl" scale="1.0 1.0 1.0"/>
      </geometry>
      <material name="wrist_gear_drive_visual_material"/>
    </visual>
  </link>
  <link name="right_wrist_pitch_drive_body">
    <inertial>
      <origin xyz="0.0 0.0 0.0" rpy="0.0 0.0 0.0"/>
      <mass value="0.001"/>
      <inertia ixx="1e-09" iyy="1e-09" izz="1e-09" ixy="0" ixz="0" iyz="0"/>
    </inertial>
  </link>
  <joint type="fixed" name="right_wrist_pitch_drive">
    <parent link="right_wrist_pitch_link"/>
    <child link="right_wrist_pitch_drive_body"/>
    <origin xyz="0.0 0.003 0.024" rpy="0.0 0.0 0.0"/>
  </joint>
  <joint type="fixed" name="right_wrist_pitch_drive_offset">
    <parent link="right_wrist_pitch_drive_body"/>
    <child link="right_wrist_gear_drive"/>
    <origin xyz="0.0 0.0 0.0" rpy="0.0 0.0 0.0"/>
  </joint>
  <link name="right_hand">
    <inertial>
      <origin xyz="-0.0203795 -0.00314939 -0.0386553" rpy="-0.0500593 -0.00457641 -0.292197"/>
      <mass value="0.043"/>
      <inertia ixx="3.0146514938647806e-05" iyy="2.638404584618489e-05" izz="1.7004039215167326e-05" ixy="0" ixz="0" iyz="0"/>
    </inertial>
    <visual name="right_hand_visual">
      <origin xyz="-0.0203795 -0.00314939 -0.0386553" rpy="0.0 0.0 0.0"/>
      <geometry>
        <mesh filename="assets/right_hand_visual.stl" scale="1.0 1.0 1.0"/>
      </geometry>
      <material name="hand_visual_material"/>
    </visual>
    <collision name="right_hand_collision">
      <origin xyz="-0.0174602 -0.0045 -0.047" rpy="0.0 0.0 0.0"/>
      <geometry>
        <box type="box" size="0.074 0.05 0.02"/>
      </geometry>
    </collision>
  </link>
  <link name="right_wrist_roll_body">
    <inertial>
      <origin xyz="0.0 0.0 0.0" rpy="0.0 0.0 0.0"/>
      <mass value="0.001"/>
      <inertia ixx="1e-09" iyy="1e-09" izz="1e-09" ixy="0" ixz="0" iyz="0"/>
    </inertial>
  </link>
  <joint type="revolute" name="right_wrist_roll">
    <parent link="right_wrist_pitch_link"/>
    <child link="right_wrist_roll_body"/>
    <origin xyz="0.019 0.022 0.0" rpy="0.0 0.0 0.0"/>
    <axis xyz="1.0 0.0 0.0"/>
    <limit lower="-1.5707963267948966" upper="1.5707963267948966" effort="100" velocity="100"/>
  </joint>
  <joint type="fixed" name="right_wrist_roll_offset">
    <parent link="right_wrist_roll_body"/>
    <child link="right_hand"/>
    <origin xyz="0.0 0.0 0.0" rpy="0.0 0.0 0.0"/>
  </joint>
  <material name="ankle_pitch_link_visual_material">
    <color rgba="0.708413 0.627926 0.367392 1"/>
  </material>
  <material name="ankle_roll_link_visual_material">
    <color rgba="0.615686 0.811765 0.929412 1"/>
  </material>
  <material name="elbow_gear_drive_visual_material">
    <color rgba="0.615686 0.811765 0.929412 1"/>
  </material>
  <material name="elbow_roll_link_visual_material">
    <color rgba="0.75922 0.862174 0.917756 1"/>
  </material>
  <material name="elbow_yaw_link_visual_material">
    <color rgba="0.460193 0.637231 0.838972 1"/>
  </material>
  <material name="hand_visual_material">
    <color rgba="0.647059 0.647059 0.647059 1"/>
  </material>
  <material name="head_visual_material">
    <color rgba="0.628184 0.794414 0.875689 1"/>
  </material>
  <material name="hip_pitch_link_visual_material">
    <color rgba="0.940459 0.715563 0.0942225 1"/>
  </material>
  <material name="hip_roll_link_visual_material">
    <color rgba="0.615686 0.811765 0.929412 1"/>
  </material>
  <material name="hip_yaw_gear_drive_visual_material">
    <color rgba="0.615686 0.811765 0.929412 1"/>
  </material>
  <material name="hip_yaw_link_visual_material">
    <color rgba="0.801331 0.729185 0.393273 1"/>
  </material>
  <material name="knee_link_visual_material">
    <color rgba="0.615686 0.811765 0.929412 1"/>
  </material>
  <material name="neck_pitch_plate_visual_material">
    <color rgba="0.647059 0.647059 0.647059 1"/>
  </material>
  <material name="neck_rod_2_visual_material">
    <color rgba="0.62596 0.757827 0.836947 1"/>
  </material>
  <material name="neck_rod_visual_material">
    <color rgba="0.62596 0.757827 0.836947 1"/>
  </material>
  <material name="neck_yaw_gear_drive_visual_material">
    <color rgba="0.647059 0.647059 0.647059 1"/>
  </material>
  <material name="neck_yaw_link_visual_material">
    <color rgba="0.231373 0.380392 0.705882 1"/>
  </material>
  <material name="pelvis_link_visual_material">
    <color rgba="0.642812 0.76997 0.800997 1"/>
  </material>
  <material name="shoulder_gear_drive_visual_material">
    <color rgba="0.615686 0.811765 0.929412 1"/>
  </material>
  <material name="shoulder_pitch_link_visual_material">
    <color rgba="0.615686 0.811765 0.929412 1"/>
  </material>
  <material name="shoulder_roll_link_visual_material">
    <color rgba="0.75922 0.862174 0.917756 1"/>
  </material>
  <material name="shoulder_yaw_link_visual_material">
    <color rgba="0.542005 0.729062 0.886557 1"/>
  </material>
  <material name="torso_visual_material">
    <color rgba="0.63539 0.796011 0.905481 1"/>
  </material>
  <material name="waist_gear_drive_2_visual_material">
    <color rgba="0.647059 0.647059 0.647059 1"/>
  </material>
  <material name="waist_gear_drive_visual_material">
    <color rgba="0.647059 0.647059 0.647059 1"/>
  </material>
  <material name="waist_gears_visual_material">
    <color rgba="0.307262 0.428048 0.687761 1"/>
  </material>
  <material name="wrist_gear_drive_visual_material">
    <color rgba="0.615686 0.811765 0.929412 1"/>
  </material>
  <material name="wrist_pitch_link_visual_material">
    <color rgba="0.748702 0.84202 0.892409 1"/>
  </material>
</robot>