<mujoco model="gen3">
  <compiler angle="radian" meshdir="assets"/>

  <option integrator="implicitfast"/>

  <default>
    <!-- kinova defaults -->
    <default class="kinova">
      <material specular="0.5" shininess="0.25"/>
      <joint armature="0.1" damping="1" axis="0 0 1" range="-2.8973 2.8973"/>
      <general dyntype="none" biastype="affine" ctrlrange="-2.8973 2.8973" forcerange="-87 87"/>
      <default class="infiniteJoints">
        <joint limited="false"/>
      </default>
      <default class="limitedJoints">
        <joint limited="true"/>
      </default>
      <site size="0.001" rgba="0.5 0.5 0.5 0.3" group="4"/>

      <default class="visual">
        <geom type="mesh" contype="0" conaffinity="0" group="2"/>
      </default>
      <default class="collision">
        <geom type="mesh" group="3"/>
      </default>
    </default>
  </default>


  <asset>
    <material class="kinova" name="blue" rgba="0.000000 0.000000 1.000000 1.000000"/>
    <material class="kinova" name="white" rgba="1.000000 1.000000 1.000000 1.000000"/>

    <!-- collision meshes -->
    <mesh name="base_link_c" file="base_link.stl"/>
    <mesh name="shoulder_link_c" file="shoulder_link.stl"/>
    <mesh name="half_arm_1_link_c" file="half_arm_1_link.stl"/>
    <mesh name="half_arm_2_link_c" file="half_arm_2_link.stl"/>
    <mesh name="forearm_link_c" file="forearm_link.stl"/>
    <mesh name="spherical_wrist_1_link_c" file="spherical_wrist_1_link.stl"/>
    <mesh name="spherical_wrist_2_link_c" file="spherical_wrist_2_link.stl"/>
    <mesh name="bracelet_with_vision_link_c" file="bracelet_with_vision_link.stl"/>

    <!-- visual meshes -->
    <mesh file="base_link_0.obj"/>
    <mesh file="base_link_1.obj"/>
    <mesh file="shoulder_link.obj"/>
    <mesh file="half_arm_1_link.obj"/>
    <mesh file="half_arm_2_link.obj"/>
    <mesh file="forearm_link.obj"/>
    <mesh file="spherical_wrist_1_link.obj"/>
    <mesh file="spherical_wrist_2_link.obj"/>
    <mesh file="bracelet_with_vision_link.obj"/>
  </asset>

  <contact>
    <exclude body1="base_link" body2="shoulder_link" />
  </contact>

  <worldbody>
    <light name="top" pos="0 0 2" mode="trackcom"/>

    <body name="base_link" gravcomp="1" pos="0 0 0" quat="1 0 0 0">
      <inertial pos="-0.000648 -0.000166 0.084487" quat="1 0 0 0" mass="1.697" diaginertia="0.004622 0.004495 0.002079"/>
      <geom mesh="base_link_0" material="blue" class="visual"/>
      <geom mesh="base_link_1" material="white" class="visual"/>
      <geom mesh="base_link_c" class="collision"/>
      <body name="shoulder_link" gravcomp="1" pos="0 0 0.15643" quat="-3.67321e-06 1 0 0">
        <inertial pos="-2.3e-05 -0.010364 -0.07336" quat="0.707051 0.0451246 -0.0453544 0.704263" mass="1.3773" diaginertia="0.00488868 0.00457 0.00135132"/>
        <joint class="infiniteJoints" name="joint_1" armature="0.0000015"/>
        <geom mesh="shoulder_link" material="white" class="visual"/>
        <geom mesh="shoulder_link_c" class="collision"/>
        <body name="half_arm_1_link" gravcomp="1" pos="0 0.005375 -0.12838" quat="0.707105 0.707108 0 0">
          <inertial pos="-4.4e-05 -0.09958 -0.013278" quat="0.482348 0.516286 -0.516862 0.483366" mass="1.1636" diaginertia="0.0113017 0.011088 0.00102532"/>
          <joint class="limitedJoints" name="joint_2" range="-2.41 2.41" armature="0.0000015"/>
          <geom mesh="half_arm_1_link" material="white" class="visual"/>
          <geom mesh="half_arm_1_link_c" class="collision"/>
          <body name="half_arm_2_link" gravcomp="1" pos="0 -0.21038 -0.006375" quat="0.707105 -0.707108 0 0">
            <inertial pos="-4.4e-05 -0.006641 -0.117892" quat="0.706144 0.0213722 -0.0209128 0.707437" mass="1.1636" diaginertia="0.0111633 0.010932 0.00100671"/>
            <joint class="infiniteJoints" name="joint_3" armature="0.0000015"/>
            <geom mesh="half_arm_2_link" material="white" class="visual"/>
            <geom mesh="half_arm_2_link_c" class="collision"/>
            <body name="forearm_link" gravcomp="1" pos="0 0.006375 -0.21038" quat="0.707105 0.707108 0 0">
              <inertial pos="-1.8e-05 -0.075478 -0.015006" quat="0.483678 0.515961 -0.515859 0.483455" mass="0.9302" diaginertia="0.00834839 0.008147 0.000598606"/>
              <joint class="limitedJoints" name="joint_4" range="-2.66 2.66" armature="0.0000015"/>
              <geom mesh="forearm_link" material="white" class="visual"/>
              <geom mesh="forearm_link_c" class="collision"/>
              <body name="spherical_wrist_1_link" gravcomp="1" pos="0 -0.20843 -0.006375" quat="0.707105 -0.707108 0 0">
                <inertial pos="1e-06 -0.009432 -0.063883" quat="0.703558 0.0707492 -0.0707492 0.703558" mass="0.6781" diaginertia="0.00165901 0.001596 0.000346988"/>
                <joint class="infiniteJoints" name="joint_5" armature="0.000001928"/>
                <geom mesh="spherical_wrist_1_link" material="white" class="visual"/>
                <geom mesh="spherical_wrist_1_link_c" class="collision"/>
                <body name="spherical_wrist_2_link" gravcomp="1" pos="0 0.00017505 -0.10593" quat="0.707105 0.707108 0 0">
                  <inertial pos="1e-06 -0.045483 -0.00965" quat="0.44426 0.550121 -0.550121 0.44426" mass="0.6781" diaginertia="0.00170087 0.001641 0.00035013"/>
                  <joint class="limitedJoints" name="joint_6" range="-2.23 2.23" armature="0.000001928"/>
                  <geom mesh="spherical_wrist_2_link" material="white" class="visual"/>
                  <geom mesh="spherical_wrist_2_link_c" class="collision"/>
                  <body name="bracelet_link" gravcomp="1" pos="0 -0.10593 -0.00017505" quat="0.707105 -0.707108 0 0">
                    <camera name="wrist_camera" pos="0.0 -0.056 -0.058" fovy="58" mode="fixed" resolution="640 480" quat="0.0 0.0 0.0 1.0"/>
                    <site name="wrist_camera_optical_frame" pos="0.0 -0.056 -0.058" quat="0.0 0.0 1.0 0.0"/>
                    <inertial pos="-9.3e-05 0.000132 -0.022905" quat="-0.0368025 0.719402 -0.0444884 0.69219" mass="0.364" diaginertia="0.00024027 0.000222769 0.000213961"/>
                    <joint class="infiniteJoints" name="joint_7" armature="0.000001928"/>
                    <geom mesh="bracelet_with_vision_link" material="white" class="visual"/>
                    <geom mesh="bracelet_with_vision_link_c" class="collision"/>
                  </body>
                </body>
              </body>
            </body>
          </body>
        </body>
      </body>
    </body>
  </worldbody>

  <actuator>
    <general class="kinova" name="joint_1" joint="joint_1" gainprm="4500" biasprm="0 -4500 -450"/>
    <general class="kinova" name="joint_2" joint="joint_2" gainprm="4500" biasprm="0 -4500 -450"/>
    <general class="kinova" name="joint_3" joint="joint_3" gainprm="3500" biasprm="0 -3500 -350"/>
    <general class="kinova" name="joint_4" joint="joint_4" gainprm="3500" biasprm="0 -3500 -350"/>
    <general class="kinova" name="joint_5" joint="joint_5" gainprm="2000" biasprm="0 -2000 -200"/>
    <general class="kinova" name="joint_6" joint="joint_6" gainprm="2000" biasprm="0 -2000 -200"/>
    <general class="kinova" name="joint_7" joint="joint_7" gainprm="2000" biasprm="0 -2000 -200"/>
  </actuator>
</mujoco>
