<mujoco model="left_inspire_hand">
    <compiler angle="radian" meshdir="assets" autolimits="true"/>
    <option cone="elliptic" impratio="10"/>
    <default>
        <default class="left_hand">
            <joint damping="3" limited="true" type="hinge"/>
            <position kp="100" ctrllimited="true" dampratio="1" inheritrange="1"/>
            <site rgba="0 0 0 0" size="0.01"/>
            <default class="collision">
                <geom contype="1" conaffinity="1" group="3" mass="0.1"/>
            </default>
            <default class="visual">
                <geom group="2" conaffinity="0" contype="0"/>
            </default>
        </default>
    </default>
    <asset>
        <mesh file="lh_base_link.stl"/>
        <mesh file="lh_palm.stl"/>
        <mesh file="lh_link11.stl"/>
        <mesh file="lh_link12.stl"/>
        <mesh file="lh_link13.stl"/>
        <mesh file="lh_link14.stl"/>
        <mesh file="lh_link15.stl"/>
        <mesh file="lh_link15_outer.stl"/>
        <mesh file="lh_link15_lower.stl" scale="1.001 1.001 1.001"/>
        <mesh file="lh_link16.stl"/>
        <mesh file="lh_link16_outer.stl" scale="1.001 1.001 1.001"/>
        <mesh file="lh_link17.stl"/>
        <mesh file="lh_link17_outer.stl"/>
        <mesh file="lh_link17_lower.stl" scale="1.001 1.001 1.001"/>
        <mesh file="lh_link18.stl"/>
        <mesh file="lh_link18_outer.stl" scale="1.02 1.01 1.01"/>
        <mesh file="lh_link19.stl"/>
        <mesh file="lh_link19_lower.stl" scale="1.01 1.01 1.01"/>
        <mesh file="lh_link19_outer.stl"/>
        <mesh file="lh_link20.stl"/>
        <mesh file="lh_link20_outer.stl" scale="1.01 1.01 1.01"/>
        <mesh file="lh_link21.stl"/>
        <mesh file="lh_link21_outer.stl"/>
        <mesh file="lh_link21_lower.stl" scale="1.001 1.001 1.001"/>
        <mesh file="lh_link22.stl"/>
        <mesh file="lh_link22_outer.stl" scale="1.01 1.01 1.01"/>
        <material name="l_white" rgba="1 1 1 1"/>
        <material name="l_black" rgba="0 0 0 1"/>
    </asset>
    <worldbody>
        <body name="left_hand" euler="0 -1.57 3.14" childclass="left_hand" gravcomp="1">
            <body name="l_base">
                <geom name="l_base_vis" type="mesh" mesh="lh_base_link" material="l_white" class="visual"/>
                <geom name="l_base_col" type="mesh" mesh="lh_base_link" class="collision"/>
                <geom name="l_palm_vis" pos="-0.0001 0 0" type="mesh" mesh="lh_palm" material="l_black" class="visual"/>
                <body name="l_thumb">
                    <body name="l_thumb_proximal_1" pos="-0.01496 -0.0375 0.02045" quat="0.5 0.5 -0.5 0.5">
                        <joint name="joint_l_thumb_proximal_1" axis="0 0 1" range="0 1.30"/>
                        <geom name="l_thumb_proximal_vis" type="mesh" mesh="lh_link11" material="l_black" class="visual"> </geom>
                        <geom name="l_thumb_proximal_col" type="mesh" mesh="lh_link11" material="l_black"
                            class="collision"/>
                        <body name="l_thumb_proximal_2" pos="0.0099867 0.0098242 -0.0089"
                            quat="0.705 -0.705 -0.060 0.060">
                            <joint name="joint_l_thumb_proximal_2" axis="0 0 -1" range="0 0.68"/>
                            <geom name="l_thumb_proximal_2_vis" type="mesh" mesh="lh_link12" material="l_black"
                                class="visual"> </geom>
                            <geom name="l_thumb_proximal_2_col" type="mesh" mesh="lh_link12" material="l_black"
                                class="collision"/>
                            <site name="site_l_thumb_proximal_2"/>
                            <body name="l_thumb_middle" pos="0.04407 -0.034553 -0.0008">
                                <joint name="joint_l_thumb_middle" axis="0 0 -1" range="0 0.68"/>
                                <geom name="l_thumb_middle_vis" type="mesh" mesh="lh_link13" material="l_white"
                                    class="visual"/>
                                <geom name="l_thumb_middle_col" type="mesh" mesh="lh_link13" material="l_white"
                                    class="collision"/>
                                <site name="site_l_thumb_middle"/>
                                <body name="l_thumb_distal" pos="0.020248 -0.010156 -0.0012">
                                    <joint name="joint_l_thumb_distal" axis="0 0 -1" range="0 0.77"/>
                                    <geom name="l_thumb_distal_vis" type="mesh" mesh="lh_link14" material="l_black"
                                        class="visual"> </geom>
                                    <geom name="l_thumb_distal_col" type="mesh" mesh="lh_link14" material="l_black"
                                        class="collision"/>
                                    <site name="site_l_thumb_distal"/>
                                </body>
                            </body>
                        </body>
                    </body>
                </body>
                <body name="l_index">
                    <body name="l_index_proximal" pos="0.0022853 -0.10493 0.032268" quat="0.99985 -0.01745 0.0 0.0">
                        <joint name="joint_l_index_proximal" axis="0 0 -1" range="0 1.62"/>
                        <site name="site_l_index_proximal"/>
                        <geom name="l_index_proximal_vis" type="mesh" mesh="lh_link15" material="l_black" class="visual"/>
                        <geom name="l_index_outer_proximal_vis" pos="0.0001 0 0" type="mesh" mesh="lh_link15_outer"
                            material="l_white" class="visual"/>
                        <geom name="l_index_lower_proximal_vis" type="mesh" mesh="lh_link15_lower" material="l_white"
                            class="visual"/>
                        <geom name="l_index_proximal_col" type="mesh" mesh="lh_link15" material="l_black"
                            class="collision"/>
                        <body name="l_index_distal" pos="-0.0024229 -0.032041 -0.001">
                            <joint name="joint_l_index_distal" axis="0 0 -1" range="0 1.82"/>
                            <site name="site_l_index_distal"/>
                            <geom name="l_index_distal_vis" type="mesh" mesh="lh_link16" material="l_black"
                                class="visual"/>
                            <geom name="l_index_outer_distal_vis" type="mesh" mesh="lh_link16_outer" material="l_white"
                                class="visual"/>
                            <geom name="l_index_distal_col" type="mesh" mesh="lh_link16" material="l_black"
                                class="collision"/>
                        </body>
                    </body>
                </body>
                <body name="l_middle">
                    <body name="l_middle_proximal" pos="0.0022853 -0.1055 0.01295">
                        <joint name="joint_l_middle_proximal" axis="0 0 -1" range="0 1.62"/>
                        <site name="site_l_middle_proximal"/>
                        <geom name="l_middle_proximal_vis" type="mesh" mesh="lh_link17" material="l_black"
                            class="visual"/>
                        <geom name="l_middle_proximal_col" type="mesh" mesh="lh_link17" material="l_black"
                            class="collision"/>
                        <geom name="l_middle_outer_proximal_vis" pos="0.0001 0 0" type="mesh" mesh="lh_link17_outer"
                            material="l_white" class="visual"/>
                        <geom name="l_middle_lower_proximal_vis" type="mesh" mesh="lh_link17_lower" material="l_white"
                            class="visual"/>
                        <body name="l_middle_distal" pos="-0.0024229 -0.032041 -0.001">
                            <joint name="joint_l_middle_distal" axis="0 0 -1" range="0 1.82"/>
                            <site name="site_l_middle_distal"/>
                            <geom name="l_middle_distal_vis" type="mesh" mesh="lh_link18" material="l_black"
                                class="visual"/>
                            <geom name="l_middle_distal_col" type="mesh" mesh="lh_link18" material="l_black"
                                class="collision"/>
                            <geom name="l_middle_outer_distal_vis" type="mesh" mesh="lh_link18_outer" material="l_white"
                                class="visual"/>
                        </body>
                    </body>
                </body>
                <body name="l_ring">
                    <body name="l_ring_proximal" pos="0.0022853 -0.10531 -0.0062872" quat="0.99966 0.02618 0.0 0.0">
                        <joint name="joint_l_ring_proximal" axis="0 0 -1" range="0 1.62"/>
                        <site name="site_l_ring_proximal"/>
                        <geom name="l_ring_proximal_vis" type="mesh" mesh="lh_link19" material="l_black" class="visual"/>
                        <geom name="l_ring_proximal_col" type="mesh" mesh="lh_link19" material="l_black"
                            class="collision"/>
                        <geom name="l_ring_outer_proximal_vis" pos="0.0001 0 0" type="mesh" mesh="lh_link19_outer"
                            material="l_white" class="visual"/>
                        <geom name="l_ring_lower_proximal_vis" type="mesh" mesh="lh_link19_lower" material="l_white"
                            class="visual"/>
                        <body name="l_ring_distal" pos="-0.0024229 -0.032041 -0.001">
                            <joint name="joint_l_ring_distal" axis="0 0 -1" range="0 1.75"/>
                            <site name="site_l_ring_distal"/>
                            <geom name="l_ring_distal_vis" type="mesh" mesh="lh_link20" material="l_black"
                                class="visual"/>
                            <geom name="l_ring_outer_distal_vis" type="mesh" mesh="lh_link20_outer" material="l_white"
                                class="visual"/>
                            <geom name="l_ring_distal_col" type="mesh" mesh="lh_link20" material="l_black"
                                class="collision"/>
                        </body>
                    </body>
                </body>
                <body name="l_pinky">
                    <body name="l_pinky_proximal" pos="0.0022853 -0.10411 -0.025488" quat="0.99863 0.05234 0.0 0.0">
                        <joint name="joint_l_pinky_proximal" axis="0 0 -1" range="0 1.62"/>
                        <site name="site_l_pinky_proximal"/>
                        <geom name="l_pinky_proximal_vis" type="mesh" mesh="lh_link21" material="l_black" class="visual"/>
                        <geom name="l_pinky_proximal_col" type="mesh" mesh="lh_link21" material="l_black"
                            class="collision"/>
                        <geom name="l_pinky_outer_proximal_vis" type="mesh" mesh="lh_link21_outer" pos="0.0001 0 0"
                            material="l_white" class="visual"/>
                        <geom name="l_pinky_lower_proximal_vis" type="mesh" mesh="lh_link21_lower" material="l_white"
                            class="visual"/>
                        <body name="l_pinky_distal" pos="-0.0024229 -0.032041 -0.001">
                            <joint name="joint_l_pinky_distal" axis="0 0 -1" range="0 1.87"/>
                            <site name="site_l_pinky_distal"/>
                            <geom name="l_pinky_distal_vis" type="mesh" mesh="lh_link22" material="l_black"
                                class="visual"/>
                            <geom name="l_pinky_distal_col" type="mesh" mesh="lh_link22" material="l_black"
                                class="collision"/>
                            <geom name="l_pinky_outer_distal_vis" type="mesh" mesh="lh_link22_outer" material="l_white"
                                class="visual"/>
                        </body>
                    </body>
                </body>
            </body>
        </body>
    </worldbody>
    <contact>
        <exclude name="exclude_lh_palm_thumb_proximal_1" body1="l_thumb_proximal_1" body2="l_base"/>
        <exclude name="exclude_lh_palm_thumb_proximal_1_proximal_2" body1="l_thumb_proximal_1"
            body2="l_thumb_proximal_2"/>
        <exclude name="exclude_lh_palm_thumb_proximal_2" body1="l_thumb_proximal_2" body2="l_base"/>
        <exclude name="exclude_lh_palm_thumb_middle_2" body1="l_thumb_middle" body2="l_base"/>
        <exclude name="exclude_lh_thumb_proximal_2_middle" body1="l_thumb_proximal_2" body2="l_thumb_middle"/>
        <exclude name="exclude_lh_thumb_middle_distal" body1="l_thumb_middle" body2="l_thumb_distal"/>
        <exclude name="exclude_lh_palm_index_proximal" body1="l_index_proximal" body2="l_base"/>
        <exclude name="exclude_lh_palm_middle_proximal" body1="l_middle_proximal" body2="l_base"/>
        <exclude name="exclude_lh_palm_ring_proximal" body1="l_ring_proximal" body2="l_base"/>
        <exclude name="exclude_lh_palm_pinky_proximal" body1="l_pinky_proximal" body2="l_base"/>
    </contact>
    <equality>
        <joint joint1="joint_l_thumb_proximal_2" joint2="joint_l_thumb_middle" polycoef="0 1.0 0 0 0"
            solimp="0.95 0.99 0.001" solref="0.005 1"/>
        <joint joint1="joint_l_thumb_proximal_2" joint2="joint_l_thumb_distal" polycoef="0 1.13 0 0 0"
            solimp="0.95 0.99 0.001" solref="0.005 1"/>
        <joint joint1="joint_l_index_proximal" joint2="joint_l_index_distal" polycoef="0 1.13 0 0 0"
            solimp="0.95 0.99 0.001" solref="0.005 1"/>
        <joint joint1="joint_l_middle_proximal" joint2="joint_l_middle_distal" polycoef="0 1.13 0 0 0"
            solimp="0.95 0.99 0.001" solref="0.005 1"/>
        <joint joint1="joint_l_ring_proximal" joint2="joint_l_ring_distal" polycoef="0 1.08 0 0 0"
            solimp="0.95 0.99 0.001" solref="0.005 1"/>
        <joint joint1="joint_l_pinky_proximal" joint2="joint_l_pinky_distal" polycoef="0 1.15 0 0 0"
            solimp="0.95 0.99 0.001" solref="0.005 1"/>
    </equality>
    <actuator>
        <position joint="joint_l_thumb_proximal_1" name="thumb_l_proximal_1_drive" class="left_hand"/>
        <position joint="joint_l_thumb_proximal_2" name="thumb_l_proximal_2_drive" class="left_hand"/>
        <position joint="joint_l_index_proximal" name="index_l_proximal_drive" class="left_hand"/>
        <position joint="joint_l_middle_proximal" name="middle_l_proximal_drive" class="left_hand"/>
        <position joint="joint_l_ring_proximal" name="ring_l_proximal_drive" class="left_hand"/>
        <position joint="joint_l_pinky_proximal" name="pinky_l_proximal_drive" class="left_hand"/>
    </actuator>

</mujoco>