<mujoco model="z1">
  <compiler angle="radian" meshdir="assets"/>

  <default>
    <default class="z1">
      <default class="visual">
        <geom type="mesh"/>
      </default>
    </default>
  </default>

  <asset>
    <mesh name="z1_Link00" file="z1_Link00.stl"/>
    <mesh name="z1_Link01" file="z1_Link01.stl"/>
    <mesh name="z1_Link02" file="z1_Link02.stl"/>
    <mesh name="z1_Link03" file="z1_Link03.stl"/>
    <mesh name="z1_Link04" file="z1_Link04.stl"/>
    <mesh name="z1_Link05" file="z1_Link05.stl"/>
    <mesh name="z1_Link06" file="z1_Link06.stl"/>
  </asset>

  <worldbody>
    <body name="link00">
      <inertial pos="-0.00334984 -0.00013615 0.0249584" quat="-0.00692194 0.682592 0.00133293 0.730766" mass="0.472475"
        diaginertia="0.000531375 0.000415207 0.000378658"/>
      <geom class="visual" mesh="z1_Link00"/>
      <body name="link01" pos="0 0 0.0585">
        <inertial pos="2.47e-06 -0.00025198 0.0231717" quat="0.708578 0.705633 0.000281462 -0.000355927" mass="0.673326"
          diaginertia="0.00128328 0.000839362 0.000719308"/>
        <joint name="joint1" pos="0 0 0" axis="0 0 1" range="-2.61799 2.61799" damping="1" frictionloss="1"/>
        <geom class="visual" mesh="z1_Link01"/>
        <body name="link02" pos="0 0 0.045">
          <inertial pos="-0.110126 0.00240029 0.00158266" quat="0.00748058 0.707092 -0.0114473 0.70699" mass="1.19132"
            diaginertia="0.0246612 0.0243113 0.00100468"/>
          <joint name="joint2" pos="0 0 0" axis="0 1 0" range="0 2.96706" damping="2" frictionloss="2"/>
          <geom class="visual" mesh="z1_Link02"/>
          <body name="link03" pos="-0.35 0 0">
            <inertial pos="0.106092 -0.00541815 0.0347638" quat="0.540557 0.443575 0.426319 0.573839" mass="0.839409"
              diaginertia="0.00954365 0.00938711 0.000558432"/>
            <joint name="joint3" pos="0 0 0" axis="0 1 0" range="-2.87979 0" damping="1" frictionloss="1"/>
            <geom class="visual" mesh="z1_Link03"/>
            <body name="link04" pos="0.218 0 0.057">
              <inertial pos="0.0436668 0.00364738 -0.00170192" quat="0.0390835 0.726445 -0.0526787 0.684087"
                mass="0.564046" diaginertia="0.000981656 0.00094053 0.000302655"/>
              <joint name="joint4" pos="0 0 0" axis="0 1 0" range="-1.51844 1.51844" damping="1" frictionloss="1"/>
              <geom class="visual" mesh="z1_Link04"/>
              <body name="link05" pos="0.07 0 0">
                <inertial pos="0.0312153 0 0.00646316" quat="0.462205 0.535209 0.53785 0.45895" mass="0.389385"
                  diaginertia="0.000558961 0.000547317 0.000167332"/>
                <joint name="joint5" pos="0 0 0" axis="0 0 1" range="-1.3439 1.3439" damping="1" frictionloss="1"/>
                <geom class="visual" mesh="z1_Link05"/>
                <body name="link06" pos="0.0492 0 0">
                  <inertial pos="0.0241569 -0.00017355 -0.00143876" quat="0.998779 0.0457735 -0.00663717 0.0173548"
                    mass="0.288758" diaginertia="0.00018333 0.000147464 0.000146786"/>
                  <joint name="joint6" pos="0 0 0" axis="1 0 0" range="-2.79253 2.79253" damping="1" frictionloss="1"/>
                  <geom class="visual" mesh="z1_Link06"/>
                </body>
              </body>
            </body>
          </body>
        </body>
      </body>
    </body>
  </worldbody>

  <actuator>
    <general name="motor1" joint="joint1"/>
    <general name="motor2" joint="joint2"/>
    <general name="motor3" joint="joint3"/>
    <general name="motor4" joint="joint4"/>
    <general name="motor5" joint="joint5"/>
    <general name="motor6" joint="joint6"/>
  </actuator>
</mujoco>